Workbook
Name _A100000: #REF!

Sheet บันทึกรายการ 63
B1: นิติบุคคลหมู่บ้านจัดสรร แมกไม้ลีลาวดี
B2: สมุดรายวันทั่วไป
B3: ตั้งแต่สวันที่ 1 มกราคม ถึง 31 พฤษภาคม 2563
I4: =SUBTOTAL(9,I6:I7183) -> 1656293.6 | J4: =SUBTOTAL(9,J6:J7183) -> 1656293.6 | K4: =J4-I4 -> 0
A5: วันที่ | B5: เลขที่บัญชี | C5: ชื่อบัญชี (เท่านั้น) | D5: เลขที่เอกสาร/ใบสำคัญ | E5: เลขที่เอกสาร/อ้างอิง | F5: รายละเอียด | G5: ชื่อบัญชี | H5: คำอธิบาย | I5: เดบิท | J5: เครดิต
A7: 242158 | B7: 1113-01 | C7: =VLOOKUP(B7,'Accounts chart'!$A:$B,2,FALSE) -> ธนาคารกสิกรไทย SA-040-1-56500-0 | D7: RVC6301001 | E7: RV6301001 | F7: 28/51 | G7: =VLOOKUP(F7,รายชื่อลูกบ้าน!$A:$B,2,FALSE) -> คุณกัญจน์ชญา เสาวกุล | H7: รับชำระค่าส่วนกลางประจำปี 2563 | I7: 7000
A8: 242158 | B8: 1113-01 | C8: =VLOOKUP(B8,'Accounts chart'!$A:$B,2,FALSE) -> ธนาคารกสิกรไทย SA-040-1-56500-0 | D8: RVC6301001 | E8: RV6301002 | F8: 28/143 | G8: =VLOOKUP(F8,รายชื่อลูกบ้าน!$A:$B,2,FALSE) -> คุณอาทิตย์ แจ่มโกมัย | H8: รับชำระค่าส่วนกลางประจำปี 2563 | I8: 7001.43
A9: 242158 | B9: 1113-01 | C9: =VLOOKUP(B9,'Accounts chart'!$A:$B,2,FALSE) -> ธนาคารกสิกรไทย SA-040-1-56500-0 | D9: RVC6301001 | E9: RV6301003 | F9: 28/29 | G9: =VLOOKUP(F9,รายชื่อลูกบ้าน!$A:$B,2,FALSE) -> คุณชญาภา มณีรัตน์ | H9: รับชำระค่าส่วนกลางประจำปี 2563 | I9: 7000
A10: 242158 | B10: 1113-01 | C10: =VLOOKUP(B10,'Accounts chart'!$A:$B,2,FALSE) -> ธนาคารกสิกรไทย SA-040-1-56500-0 | D10: RVC6301001 | E10: RV6301004 | F10: 28/109 | G10: =VLOOKUP(F10,รายชื่อลูกบ้าน!$A:$B,2,FALSE) -> คุณเสกสิทธิ์ คำธานี | H10: รับชำระค่าส่วนกลางประจำเดือน ธันวาคม 2562 | I10: 601.09
A11: 242158 | B11: 1113-01 | C11: =VLOOKUP(B11,'Accounts chart'!$A:$B,2,FALSE) -> ธนาคารกสิกรไทย SA-040-1-56500-0 | D11: RVC6301001 | E11: RV6301005 | F11: 28/54 | G11: =VLOOKUP(F11,รายชื่อลูกบ้าน!$A:$B,2,FALSE) -> คุณนาตยา-คุณนนทิยา บุญประคม | H11: รับชำระค่าส่วนกลางประจำปี 2563 | I11: 7000
A12: 242158 | B12: 4100-01 | C12: =VLOOKUP(B12,'Accounts chart'!$A:$B,2,FALSE) -> รายรับค่าส่วนกลาง | D12: RVC6301001 | E12: RV6301001 | F12: 28/51 | G12: =VLOOKUP(F12,รายชื่อลูกบ้าน!$A:$B,2,FALSE) -> คุณกัญจน์ชญา เสาวกุล | H12: รับชำระค่าส่วนกลางประจำปี 2563 | J12: 7000
A13: 242158 | B13: 4100-01 | C13: =VLOOKUP(B13,'Accounts chart'!$A:$B,2,FALSE) -> รายรับค่าส่วนกลาง | D13: RVC6301001 | E13: RV6301002 | F13: 28/143 | G13: =VLOOKUP(F13,รายชื่อลูกบ้าน!$A:$B,2,FALSE) -> คุณอาทิตย์ แจ่มโกมัย | H13: รับชำระค่าส่วนกลางประจำปี 2563 | J13: 7001.43
A14: 242158 | B14: 4100-01 | C14: =VLOOKUP(B14,'Accounts chart'!$A:$B,2,FALSE) -> รายรับค่าส่วนกลาง | D14: RVC6301001 | E14: RV6301003 | F14: 28/29 | G14: =VLOOKUP(F14,รายชื่อลูกบ้าน!$A:$B,2,FALSE) -> คุณชญาภา มณีรัตน์ | H14: รับชำระค่าส่วนกลางประจำปี 2563 | J14: 7000
A15: 242158 | B15: 1130-01 | C15: =VLOOKUP(B15,'Accounts chart'!$A:$B,2,FALSE) -> ลูกหนี้ค่าส่วนกลาง | D15: RVC6301001 | E15: RV6301004 | F15: 28/109 | G15: =VLOOKUP(F15,รายชื่อลูกบ้าน!$A:$B,2,FALSE) -> คุณเสกสิทธิ์ คำธานี | H15: รับชำระค่าส่วนกลางประจำเดือน ธันวาคม 2562 | J15: 601.09
A16: 242158 | B16: 4100-01 | C16: =VLOOKUP(B16,'Accounts chart'!$A:$B,2,FALSE) -> รายรับค่าส่วนกลาง | D16: RVC6301001 | E16: RV6301005 | F16: 28/54 | G16: =VLOOKUP(F16,รายชื่อลูกบ้าน!$A:$B,2,FALSE) -> คุณนาตยา-คุณนนทิยา บุญประคม | H16: รับชำระค่าส่วนกลางประจำปี 2563 | J16: 7000
A19: 242159 | B19: 1113-01 | C19: =VLOOKUP(B19,'Accounts chart'!$A:$B,2,FALSE) -> ธนาคารกสิกรไทย SA-040-1-56500-0 | D19: RVC6301002 | E19: RV6301006 | F19: 28/74 | G19: =VLOOKUP(F19,รายชื่อลูกบ้าน!$A:$B,2,FALSE) -> คุณวุฒินันท์ สงนารถ | H19: รับชำระค่าส่วนกลางประจำปี 2563 | I19: 7000.63
A20: 242159 | B20: 1113-01 | C20: =VLOOKUP(B20,'Accounts chart'!$A:$B,2,FALSE) -> ธนาคารกสิกรไทย SA-040-1-56500-0 | D20: RVC6301002 | E20: RV6301007 | F20: 28/16 | G20: =VLOOKUP(F20,รายชื่อลูกบ้าน!$A:$B,2,FALSE) -> คุณสถิตย์ ปาระพิมพ์ | H20: รับชำระค่าส่วนกลางประจำเดือน ธันวาคม 2562 | I20: 600
A21: 242159 | B21: 1113-01 | C21: =VLOOKUP(B21,'Accounts chart'!$A:$B,2,FALSE) -> ธนาคารกสิกรไทย SA-040-1-56500-0 | D21: RVC6301002 | E21: RV6301008 | F21: 28/13 | G21: =VLOOKUP(F21,รายชื่อลูกบ้าน!$A:$B,2,FALSE) -> คุณธนัญกรณ์ ทาสระคู | H21: รับชำระค่าส่วนกลางประจำเดือน กุมภาพันธ์ 2563 | I21: 600.13
A22: 242159 | B22: 1113-01 | C22: =VLOOKUP(B22,'Accounts chart'!$A:$B,2,FALSE) -> ธนาคารกสิกรไทย SA-040-1-56500-0 | D22: RVC6301002 | E22: RV6301009 | F22: 28/113 | G22: =VLOOKUP(F22,รายชื่อลูกบ้าน!$A:$B,2,FALSE) -> คุณพวงพุฒ คาร์เตอร์ | H22: รับชำระค่าส่วนกลางประจำเดือน มกราคม - มีนาคม 2563 | I22: 1801.13
A23: 242159 | B23: 1113-01 | C23: =VLOOKUP(B23,'Accounts chart'!$A:$B,2,FALSE) -> ธนาคารกสิกรไทย SA-040-1-56500-0 | D23: RVC6301002 | E23: RV6301010 | F23: 28/77 | G23: =VLOOKUP(F23,รายชื่อลูกบ้าน!$A:$B,2,FALSE) -> คุณถวิล เคสา | H23: รับชำระค่าส่วนกลางประจำเดือน มกราคม 2563 | I23: 600
A24: 242159 | B24: 1113-01 | C24: =VLOOKUP(B24,'Accounts chart'!$A:$B,2,FALSE) -> ธนาคารกสิกรไทย SA-040-1-56500-0 | D24: RVC6301002 | E24: RV6301011 | F24: 28/156 | G24: =VLOOKUP(F24,รายชื่อลูกบ้าน!$A:$B,2,FALSE) -> คุณสุริยา ใจมา | H24: รับชำระค่าส่วนกลางประจำเดือน มกราคม 2563 | I24: 600 | Q24: _
A25: 242159 | B25: 1113-01 | C25: =VLOOKUP(B25,'Accounts chart'!$A:$B,2,FALSE) -> ธนาคารกสิกรไทย SA-040-1-56500-0 | D25: RVC6301002 | E25: RV6301012 | F25: 28/103 | G25: =VLOOKUP(F25,รายชื่อลูกบ้าน!$A:$B,2,FALSE) -> คุณดนัย ฮาวต่อมแก้ว | H25: รับชำระค่าส่วนกลางประจำเดือน ธันวาคม 2562 | I25: 600
A26: 242159 | B26: 4100-01 | C26: =VLOOKUP(B26,'Accounts chart'!$A:$B,2,FALSE) -> รายรับค่าส่วนกลาง | D26: RVC6301002 | E26: RV6301006 | F26: 28/74 | G26: =VLOOKUP(F26,รายชื่อลูกบ้าน!$A:$B,2,FALSE) -> คุณวุฒินันท์ สงนารถ | H26: รับชำระค่าส่วนกลางประจำปี 2563 | J26: 7000.63
A27: 242159 | B27: 1130-01 | C27: =VLOOKUP(B27,'Accounts chart'!$A:$B,2,FALSE) -> ลูกหนี้ค่าส่วนกลาง | D27: RVC6301002 | E27: RV6301007 | F27: 28/16 | G27: =VLOOKUP(F27,รายชื่อลูกบ้าน!$A:$B,2,FALSE) -> คุณสถิตย์ ปาระพิมพ์ | H27: รับชำระค่าส่วนกลางประจำเดือน ธันวาคม 2562 | J27: 600
A28: 242159 | B28: 4100-01 | C28: =VLOOKUP(B28,'Accounts chart'!$A:$B,2,FALSE) -> รายรับค่าส่วนกลาง | D28: RVC6301002 | E28: RV6301008 | F28: 28/13 | G28: =VLOOKUP(F28,รายชื่อลูกบ้าน!$A:$B,2,FALSE) -> คุณธนัญกรณ์ ทาสระคู | H28: รับชำระค่าส่วนกลางประจำเดือน กุมภาพันธ์ 2563 | J28: 600.13
A29: 242159 | B29: 4100-01 | C29: =VLOOKUP(B29,'Accounts chart'!$A:$B,2,FALSE) -> รายรับค่าส่วนกลาง | D29: RVC6301002 | E29: RV6301009 | F29: 28/113 | G29: =VLOOKUP(F29,รายชื่อลูกบ้าน!$A:$B,2,FALSE) -> คุณพวงพุฒ คาร์เตอร์ | H29: รับชำระค่าส่วนกลางประจำเดือน มกราคม - มีนาคม 2563 | J29: 1801.13
A30: 242159 | B30: 4100-01 | C30: =VLOOKUP(B30,'Accounts chart'!$A:$B,2,FALSE) -> รายรับค่าส่วนกลาง | D30: RVC6301002 | E30: RV6301010 | F30: 28/77 | G30: =VLOOKUP(F30,รายชื่อลูกบ้าน!$A:$B,2,FALSE) -> คุณถวิล เคสา | H30: รับชำระค่าส่วนกลางประจำเดือน มกราคม 2563 | J30: 600
A31: 242159 | B31: 4100-01 | C31: =VLOOKUP(B31,'Accounts chart'!$A:$B,2,FALSE) -> รายรับค่าส่วนกลาง | D31: RVC6301002 | E31: RV6301011 | F31: 28/156 | G31: =VLOOKUP(F31,รายชื่อลูกบ้าน!$A:$B,2,FALSE) -> คุณสุริยา ใจมา | H31: รับชำระค่าส่วนกลางประจำเดือน มกราคม 2563 | J31: 600
A32: 242159 | B32: 1130-01 | C32: =VLOOKUP(B32,'Accounts chart'!$A:$B,2,FALSE) -> ลูกหนี้ค่าส่วนกลาง | D32: RVC6301002 | E32: RV6301012 | F32: 28/103 | G32: =VLOOKUP(F32,รายชื่อลูกบ้าน!$A:$B,2,FALSE) -> คุณดนัย ฮาวต่อมแก้ว | H32: รับชำระค่าส่วนกลางประจำเดือน ธันวาคม 2562 | J32: 600
A34: 242160 | B34: 1113-01 | C34: =VLOOKUP(B34,'Accounts chart'!$A:$B,2,FALSE) -> ธนาคารกสิกรไทย SA-040-1-56500-0 | D34: RVC6301003 | E34: RV6301013 | F34: 28/131 | G34: =VLOOKUP(F34,รายชื่อลูกบ้าน!$A:$B,2,FALSE) -> คุณอรรณพ แสงประทีป | H34: รับชำระค่าส่วนกลางประจำปี 2563 | I34: 7000
A35: 242160 | B35: 1113-01 | C35: =VLOOKUP(B35,'Accounts chart'!$A:$B,2,FALSE) -> ธนาคารกสิกรไทย SA-040-1-56500-0 | D35: RVC6301003 | E35: RV6301014 | F35: 28/79 | G35: =VLOOKUP(F35,รายชื่อลูกบ้าน!$A:$B,2,FALSE) -> คุณชนะ ศรีคำ | H35: รับชำระค่าส่วนกลางประจำปี 2563 | I35: 7000
A36: 242160 | B36: 1113-01 | C36: =VLOOKUP(B36,'Accounts chart'!$A:$B,2,FALSE) -> ธนาคารกสิกรไทย SA-040-1-56500-0 | D36: RVC6301003 | E36: RV6301015 | F36: 28/81 | G36: =VLOOKUP(F36,รายชื่อลูกบ้าน!$A:$B,2,FALSE) -> คุณวิทยา วัดเข้าหลาม | H36: รับชำระค่าส่วนกลางประจำเดือน มกราคม 2563 | I36: 600.81
A37: 242160 | B37: 1113-01 | C37: =VLOOKUP(B37,'Accounts chart'!$A:$B,2,FALSE) -> ธนาคารกสิกรไทย SA-040-1-56500-0 | D37: RVC6301003 | E37: RV6301016 | F37: 28/3 | G37: =VLOOKUP(F37,รายชื่อลูกบ้าน!$A:$B,2,FALSE) -> คุณฉัตร์ชัย วานิชสมบัติ | H37: รับชำระค่าส่วนกลางประจำปี 2563 | I37: 7000
A38: 242160 | B38: 1113-01 | C38: =VLOOKUP(B38,'Accounts chart'!$A:$B,2,FALSE) -> ธนาคารกสิกรไทย SA-040-1-56500-0 | D38: RVC6301003 | E38: RV6301017 | F38: 28/117 | G38: =VLOOKUP(F38,รายชื่อลูกบ้าน!$A:$B,2,FALSE) -> คุณภานุรังสิทธิ์-คุณภญาดา หมื่นจันทร์ | H38: รับชำระค่าส่วนกลางประจำเดือน มกราคม 2563 | I38: 600
A39: 242160 | B39: 1113-01 | C39: =VLOOKUP(B39,'Accounts chart'!$A:$B,2,FALSE) -> ธนาคารกสิกรไทย SA-040-1-56500-0 | D39: RVC6301003 | E39: RV6301018 | F39: 28/14 | G39: =VLOOKUP(F39,รายชื่อลูกบ้าน!$A:$B,2,FALSE) -> คุณด้ามพรรณ ตั้งทองจิตร-คุณศราวุธ ฑพธาภิรมย์ | H39: รับชำระค่าส่วนกลางเดือน พฤศจิกายน 2562 | I39: 600
A40: 242160 | B40: 1113-01 | C40: =VLOOKUP(B40,'Accounts chart'!$A:$B,2,FALSE) -> ธนาคารกสิกรไทย SA-040-1-56500-0 | D40: RVC6301003 | E40: RV6301019 | G40: =VLOOKUP(F40,รายชื่อลูกบ้าน!$A:$B,2,FALSE) -> #N/A | H40: ไม่ทราบชื่อ | I40: 600
A41: 242160 | B41: 1113-01 | C41: =VLOOKUP(B41,'Accounts chart'!$A:$B,2,FALSE) -> ธนาคารกสิกรไทย SA-040-1-56500-0 | D41: RVC6301003 | E41: RV6301020 | F41: 28/95 | G41: =VLOOKUP(F41,รายชื่อลูกบ้าน!$A:$B,2,FALSE) -> คุณไชยยันต์ แก้วบุญศรี | H41: รับชำระค่าส่วนกลางประจำเดือน มกราคม 2563 | I41: 600.95
A42: 242160 | B42: 4100-01 | C42: =VLOOKUP(B42,'Accounts chart'!$A:$B,2,FALSE) -> รายรับค่าส่วนกลาง | D42: RVC6301003 | E42: RV6301013 | F42: 28/131 | G42: =VLOOKUP(F42,รายชื่อลูกบ้าน!$A:$B,2,FALSE) -> คุณอรรณพ แสงประทีป | H42: รับชำระค่าส่วนกลางประจำปี 2563 | J42: 7000
A43: 242160 | B43: 4100-01 | C43: =VLOOKUP(B43,'Accounts chart'!$A:$B,2,FALSE) -> รายรับค่าส่วนกลาง | D43: RVC6301003 | E43: RV6301014 | F43: 28/79 | G43: =VLOOKUP(F43,รายชื่อลูกบ้าน!$A:$B,2,FALSE) -> คุณชนะ ศรีคำ | H43: รับชำระค่าส่วนกลางประจำปี 2563 | J43: 7000
A44: 242160 | B44: 4100-01 | C44: =VLOOKUP(B44,'Accounts chart'!$A:$B,2,FALSE) -> รายรับค่าส่วนกลาง | D44: RVC6301003 | E44: RV6301015 | F44: 28/81 | G44: =VLOOKUP(F44,รายชื่อลูกบ้าน!$A:$B,2,FALSE) -> คุณวิทยา วัดเข้าหลาม | H44: รับชำระค่าส่วนกลางประจำเดือน มกราคม 2563 | J44: 600.81
...

Sheet Statement 63
C1: นิติบุคคลหมู่บ้านจัดสรร แมกไม้ลีลาวดี
C2: รายงานแสดงฐานะทางการเงิน และ รายรับรายจ่าย มกราคม - พฤษภาคม 2563
A3: เลขที่บัญชี | B3: ชือบัญชี | C3: ยอดยกมา ธ.ค.62 | D3: ม.ค.63 Dr. | E3: ม.ค.63 Cr. | F3: ม.ค.63 | G3: ก.พ.63 Dr. | H3: ก.พ.63 Cr. | I3: ก.พ.63 | J3: มี.ค.63 Dr. | K3: มี.ค.63 Cr. | L3: มี.ค.63 | M3: เม.ย.63 Dr. | N3: เม.ย.63 Cr. | O3: เม.ย.63 | P3: พ.ค.63 Dr. | Q3: พ.ค.63 Cr. | R3: พ.ค.63 | S3: รวม มกราคม - พฤษภาคม 2563
B4: รายงานแสดงฐานะทางการเงิน
A5: 1111-00 | B5: เงินสด | C5: 5000 | D5: =SUMIF('บันทึกรายการ 63'!$B$7:$B$254,'Statement 63'!A5,'บันทึกรายการ 63'!$I$7:$I$254) -> 0 | E5: =SUMIF('บันทึกรายการ 63'!$B$7:$B$254,'Statement 63'!A5,'บันทึกรายการ 63'!$J$7:$J$254) -> 0 | F5: =C5+D5-E5 -> 5000 | G5: =SUMIF('บันทึกรายการ 63'!$B$257:$B$467,'Statement 63'!A5,'บันทึกรายการ 63'!$I$257:$I$467) -> 0 | H5: =SUMIF('บันทึกรายการ 63'!$B$257:$B$467,'Statement 63'!A5,'บันทึกรายการ 63'!$J$257:$J$467) -> 5000 | I5: =F5+G5-H5 -> 0 | J5: =SUMIF('บันทึกรายการ 63'!$B$471:$B$647,'Statement 63'!A5,'บันทึกรายการ 63'!$I$471:$I$647) -> 2 | K5: =SUMIF('บันทึกรายการ 63'!$B$471:$B$647,'Statement 63'!A5,'บันทึกรายการ 63'!$J$471:$J$647) -> 0 | L5: =I5+J5-K5 -> 2 | M5: =SUMIF('บันทึกรายการ 63'!$B$649:$B$819,'Statement 63'!A5,'บันทึกรายการ 63'!$I$649:$I$819) -> 0 | N5: =SUMIF('บันทึกรายการ 63'!$B$649:$B$819,'Statement 63'!A5,'บันทึกรายการ 63'!$J$649:$J$819) -> 0 | O5: =L5+M5-N5 -> 2 | P5: =SUMIF('บันทึกรายการ 63'!$B$822:$B$994,'Statement 63'!A5,'บันทึกรายการ 63'!$I$822:$I$994) -> 0 | Q5: =SUMIF('บันทึกรายการ 63'!$B$822:$B$994,'Statement 63'!A5,'บันทึกรายการ 63'!$J$822:$J$994) -> 0 | R5: =O5+P5-Q5 -> 2 | S5: =R5 -> 2
A6: 1112-01 | B6: ธนาคารกสิกรไทย CA-040-1-57563-4 | C6: 198050.55 | D6: =SUMIF('บันทึกรายการ 63'!$B$7:$B$254,'Statement 63'!A6,'บันทึกรายการ 63'!$I$7:$I$254) -> 0 | E6: =SUMIF('บันทึกรายการ 63'!$B$7:$B$254,'Statement 63'!A6,'บันทึกรายการ 63'!$J$7:$J$254) -> 135561.64 | F6: =C6+D6-E6 -> 62488.91 | G6: =SUMIF('บันทึกรายการ 63'!$B$257:$B$467,'Statement 63'!A6,'บันทึกรายการ 63'!$I$257:$I$467) -> 200000 | H6: =SUMIF('บันทึกรายการ 63'!$B$257:$B$467,'Statement 63'!A6,'บันทึกรายการ 63'!$J$257:$J$467) -> 106522 | I6: =F6+G6-H6 -> 155966.91 | J6: =SUMIF('บันทึกรายการ 63'!$B$471:$B$647,'Statement 63'!A6,'บันทึกรายการ 63'!$I$471:$I$647) -> 0 | K6: =SUMIF('บันทึกรายการ 63'!$B$471:$B$647,'Statement 63'!A6,'บันทึกรายการ 63'!$J$471:$J$647) -> 60003.66 | L6: =I6+J6-K6 -> 95963.25 | M6: =SUMIF('บันทึกรายการ 63'!$B$649:$B$819,'Statement 63'!A6,'บันทึกรายการ 63'!$I$649:$I$819) -> 0 | N6: =SUMIF('บันทึกรายการ 63'!$B$649:$B$819,'Statement 63'!A6,'บันทึกรายการ 63'!$J$649:$J$819) -> 72258.09 | O6: =L6+M6-N6 -> 23705.16 | P6: =SUMIF('บันทึกรายการ 63'!$B$822:$B$994,'Statement 63'!A6,'บันทึกรายการ 63'!$I$822:$I$994) -> 100000 | Q6: =SUMIF('บันทึกรายการ 63'!$B$822:$B$994,'Statement 63'!A6,'บันทึกรายการ 63'!$J$822:$J$994) -> 52753.68 | R6: =O6+P6-Q6 -> 70951.48 | S6: =R6 -> 70951.48
A7: 1113-01 | B7: ธนาคารกสิกรไทย SA-040-1-56500-0 | C7: 735946.99 | D7: =SUMIF('บันทึกรายการ 63'!$B$7:$B$254,'Statement 63'!A7,'บันทึกรายการ 63'!$I$7:$I$254) -> 236011.79 | E7: =SUMIF('บันทึกรายการ 63'!$B$7:$B$254,'Statement 63'!A7,'บันทึกรายการ 63'!$J$7:$J$254) -> 0 | F7: =C7+D7-E7 -> 971958.78 | G7: =SUMIF('บันทึกรายการ 63'!$B$257:$B$467,'Statement 63'!A7,'บันทึกรายการ 63'!$I$257:$I$467) -> 122004.69 | H7: =SUMIF('บันทึกรายการ 63'!$B$257:$B$467,'Statement 63'!A7,'บันทึกรายการ 63'!$J$257:$J$467) -> 203000 | I7: =F7+G7-H7 -> 890963.47 | J7: =SUMIF('บันทึกรายการ 63'!$B$471:$B$647,'Statement 63'!A7,'บันทึกรายการ 63'!$I$471:$I$647) -> 58004.12 | K7: =SUMIF('บันทึกรายการ 63'!$B$471:$B$647,'Statement 63'!A7,'บันทึกรายการ 63'!$J$471:$J$647) -> 15000 | L7: =I7+J7-K7 -> 933967.59 | M7: =SUMIF('บันทึกรายการ 63'!$B$649:$B$819,'Statement 63'!A7,'บันทึกรายการ 63'!$I$649:$I$819) -> 55806.41 | N7: =SUMIF('บันทึกรายการ 63'!$B$649:$B$819,'Statement 63'!A7,'บันทึกรายการ 63'!$J$649:$J$819) -> 0 | O7: =L7+M7-N7 -> 989774 | P7: =SUMIF('บันทึกรายการ 63'!$B$822:$B$994,'Statement 63'!A7,'บันทึกรายการ 63'!$I$822:$I$994) -> 64104.46 | Q7: =SUMIF('บันทึกรายการ 63'!$B$822:$B$994,'Statement 63'!A7,'บันทึกรายการ 63'!$J$822:$J$994) -> 115000 | R7: =O7+P7-Q7 -> 938878.46 | S7: =R7 -> 938878.46
A8: 1130-01 | B8: ลูกหนี้ค่าส่วนกลาง | C8: 376200 | D8: =SUMIF('บันทึกรายการ 63'!$B$7:$B$254,'Statement 63'!A8,'บันทึกรายการ 63'!$I$7:$I$254) -> 0 | E8: =SUMIF('บันทึกรายการ 63'!$B$7:$B$254,'Statement 63'!A8,'บันทึกรายการ 63'!$J$7:$J$254) -> 34802.31 | F8: =C8+D8-E8 -> 341397.69 | G8: =SUMIF('บันทึกรายการ 63'!$B$257:$B$467,'Statement 63'!A8,'บันทึกรายการ 63'!$I$257:$I$467) -> 0 | H8: =SUMIF('บันทึกรายการ 63'!$B$257:$B$467,'Statement 63'!A8,'บันทึกรายการ 63'!$J$257:$J$467) -> 25200 | I8: =F8+G8-H8 -> 316197.69 | J8: =SUMIF('บันทึกรายการ 63'!$B$471:$B$647,'Statement 63'!A8,'บันทึกรายการ 63'!$I$471:$I$647) -> 0 | K8: =SUMIF('บันทึกรายการ 63'!$B$471:$B$647,'Statement 63'!A8,'บันทึกรายการ 63'!$J$471:$J$647) -> 7800 | L8: =I8+J8-K8 -> 308397.69 | M8: =SUMIF('บันทึกรายการ 63'!$B$649:$B$819,'Statement 63'!A8,'บันทึกรายการ 63'!$I$649:$I$819) -> 0 | N8: =SUMIF('บันทึกรายการ 63'!$B$649:$B$819,'Statement 63'!A8,'บันทึกรายการ 63'!$J$649:$J$819) -> 0 | O8: =L8+M8-N8 -> 308397.69 | P8: =SUMIF('บันทึกรายการ 63'!$B$822:$B$994,'Statement 63'!A8,'บันทึกรายการ 63'!$I$822:$I$994) -> 0 | Q8: =SUMIF('บันทึกรายการ 63'!$B$822:$B$994,'Statement 63'!A8,'บันทึกรายการ 63'!$J$822:$J$994) -> 4800 | R8: =O8+P8-Q8 -> 303597.69 | S8: =R8 -> 303597.69
A9: 1151-02 | B9: ภาษีถูกหัก ณ ที่จ่ายล่วงหน้า | C9: 18.71 | D9: =SUMIF('บันทึกรายการ 63'!$B$7:$B$254,'Statement 63'!A9,'บันทึกรายการ 63'!$I$7:$I$254) -> 0 | E9: =SUMIF('บันทึกรายการ 63'!$B$7:$B$254,'Statement 63'!A9,'บันทึกรายการ 63'!$J$7:$J$254) -> 0 | F9: =C9+D9-E9 -> 18.71 | G9: =SUMIF('บันทึกรายการ 63'!$B$257:$B$467,'Statement 63'!A9,'บันทึกรายการ 63'!$I$257:$I$467) -> 0 | H9: =SUMIF('บันทึกรายการ 63'!$B$257:$B$467,'Statement 63'!A9,'บันทึกรายการ 63'!$J$257:$J$467) -> 0 | I9: =F9+G9-H9 -> 18.71 | J9: =SUMIF('บันทึกรายการ 63'!$B$471:$B$647,'Statement 63'!A9,'บันทึกรายการ 63'!$I$471:$I$647) -> 0 | K9: =SUMIF('บันทึกรายการ 63'!$B$471:$B$647,'Statement 63'!A9,'บันทึกรายการ 63'!$J$471:$J$647) -> 0 | L9: =I9+J9-K9 -> 18.71 | M9: =SUMIF('บันทึกรายการ 63'!$B$649:$B$819,'Statement 63'!A9,'บันทึกรายการ 63'!$I$649:$I$819) -> 0 | N9: =SUMIF('บันทึกรายการ 63'!$B$649:$B$819,'Statement 63'!A9,'บันทึกรายการ 63'!$J$649:$J$819) -> 0 | O9: =L9+M9-N9 -> 18.71 | P9: =SUMIF('บันทึกรายการ 63'!$B$822:$B$994,'Statement 63'!A9,'บันทึกรายการ 63'!$I$822:$I$994) -> 0 | Q9: =SUMIF('บันทึกรายการ 63'!$B$822:$B$994,'Statement 63'!A9,'บันทึกรายการ 63'!$J$822:$J$994) -> 0 | R9: =O9+P9-Q9 -> 18.71 | S9: =R9 -> 18.71
A10: 1152-00 | B10: เงินทดลองจ่าย (สำรองจ่าย) | C10: 1867.05 | D10: =SUMIF('บันทึกรายการ 63'!$B$7:$B$254,'Statement 63'!A10,'บันทึกรายการ 63'!$I$7:$I$254) -> 0 | E10: =SUMIF('บันทึกรายการ 63'!$B$7:$B$254,'Statement 63'!A10,'บันทึกรายการ 63'!$J$7:$J$254) -> 0 | F10: =C10+D10-E10 -> 1867.05 | G10: =SUMIF('บันทึกรายการ 63'!$B$257:$B$467,'Statement 63'!A10,'บันทึกรายการ 63'!$I$257:$I$467) -> 10000 | H10: =SUMIF('บันทึกรายการ 63'!$B$257:$B$467,'Statement 63'!A10,'บันทึกรายการ 63'!$J$257:$J$467) -> 0 | I10: =F10+G10-H10 -> 11867.05 | J10: =SUMIF('บันทึกรายการ 63'!$B$471:$B$647,'Statement 63'!A10,'บันทึกรายการ 63'!$I$471:$I$647) -> 0 | K10: =SUMIF('บันทึกรายการ 63'!$B$471:$B$647,'Statement 63'!A10,'บันทึกรายการ 63'!$J$471:$J$647) -> 10000 | L10: =I10+J10-K10 -> 1867.05 | M10: =SUMIF('บันทึกรายการ 63'!$B$649:$B$819,'Statement 63'!A10,'บันทึกรายการ 63'!$I$649:$I$819) -> 0 | N10: =SUMIF('บันทึกรายการ 63'!$B$649:$B$819,'Statement 63'!A10,'บันทึกรายการ 63'!$J$649:$J$819) -> 0 | O10: =L10+M10-N10 -> 1867.05 | P10: =SUMIF('บันทึกรายการ 63'!$B$822:$B$994,'Statement 63'!A10,'บันทึกรายการ 63'!$I$822:$I$994) -> 0 | Q10: =SUMIF('บันทึกรายการ 63'!$B$822:$B$994,'Statement 63'!A10,'บันทึกรายการ 63'!$J$822:$J$994) -> 10000 | R10: =O10+P10-Q10 -> -8132.95 | S10: =R10 -> -8132.95
A11: 1410-07 | B11: เครื่องตกแต่งสำนักงาน | C11: 19450 | D11: =SUMIF('บันทึกรายการ 63'!$B$7:$B$254,'Statement 63'!A11,'บันทึกรายการ 63'!$I$7:$I$254) -> 0 | E11: =SUMIF('บันทึกรายการ 63'!$B$7:$B$254,'Statement 63'!A11,'บันทึกรายการ 63'!$J$7:$J$254) -> 0 | F11: =C11+D11-E11 -> 19450 | G11: =SUMIF('บันทึกรายการ 63'!$B$257:$B$467,'Statement 63'!A11,'บันทึกรายการ 63'!$I$257:$I$467) -> 0 | H11: =SUMIF('บันทึกรายการ 63'!$B$257:$B$467,'Statement 63'!A11,'บันทึกรายการ 63'!$J$257:$J$467) -> 0 | I11: =F11+G11-H11 -> 19450 | J11: =SUMIF('บันทึกรายการ 63'!$B$471:$B$647,'Statement 63'!A11,'บันทึกรายการ 63'!$I$471:$I$647) -> 0 | K11: =SUMIF('บันทึกรายการ 63'!$B$471:$B$647,'Statement 63'!A11,'บันทึกรายการ 63'!$J$471:$J$647) -> 0 | L11: =I11+J11-K11 -> 19450 | M11: =SUMIF('บันทึกรายการ 63'!$B$649:$B$819,'Statement 63'!A11,'บันทึกรายการ 63'!$I$649:$I$819) -> 0 | N11: =SUMIF('บันทึกรายการ 63'!$B$649:$B$819,'Statement 63'!A11,'บันทึกรายการ 63'!$J$649:$J$819) -> 0 | O11: =L11+M11-N11 -> 19450 | P11: =SUMIF('บันทึกรายการ 63'!$B$822:$B$994,'Statement 63'!A11,'บันทึกรายการ 63'!$I$822:$I$994) -> 0 | Q11: =SUMIF('บันทึกรายการ 63'!$B$822:$B$994,'Statement 63'!A11,'บันทึกรายการ 63'!$J$822:$J$994) -> 0 | R11: =O11+P11-Q11 -> 19450 | S11: =R11 -> 19450
B12: รวมสินทรัพย์ | C12: =SUM(C5:C11) -> 1336533.3 | D12: =SUM(D5:D11) -> 236011.79 | E12: =SUM(E5:E11) -> 170363.95 | F12: =SUM(F5:F11) -> 1402181.1 | G12: =SUM(G5:G11) -> 332004.69 | H12: =SUM(H5:H11) -> 339722 | I12: =SUM(I5:I11) -> 1394463.8 | J12: =SUM(J5:J11) -> 58006.12 | ... S12: =SUM(S5:S11) -> 1324765.4
A14: 2120-02 | B14: เช็คจ่ายล่วงหน้า | C14: 0 | D14: =SUMIF('บันทึกรายการ 63'!$B$7:$B$254,'Statement 63'!A14,'บันทึกรายการ 63'!$I$7:$I$254) -> 0 | E14: =SUMIF('บันทึกรายการ 63'!$B$7:$B$254,'Statement 63'!A14,'บันทึกรายการ 63'!$J$7:$J$254) -> 0 | F14: =C14+E14-D14 -> 0 | G14: =SUMIF('บันทึกรายการ 63'!$B$257:$B$467,'Statement 63'!A14,'บันทึกรายการ 63'!$I$257:$I$467) -> 0 | H14: =SUMIF('บันทึกรายการ 63'!$B$257:$B$467,'Statement 63'!A14,'บันทึกรายการ 63'!$J$257:$J$467) -> 0 | I14: =F14+H14-G14 -> 0 | J14: =SUMIF('บันทึกรายการ 63'!$B$471:$B$647,'Statement 63'!A14,'บันทึกรายการ 63'!$I$471:$I$647) -> 0 | K14: =SUMIF('บันทึกรายการ 63'!$B$471:$B$647,'Statement 63'!A14,'บันทึกรายการ 63'!$J$471:$J$647) -> 0 | L14: =I14+K14-J14 -> 0 | M14: =SUMIF('บันทึกรายการ 63'!$B$649:$B$819,'Statement 63'!A14,'บันทึกรายการ 63'!$I$649:$I$819) -> 0 | N14: =SUMIF('บันทึกรายการ 63'!$B$649:$B$819,'Statement 63'!A14,'บันทึกรายการ 63'!$J$649:$J$819) -> 0 | O14: =L14+N14-M14 -> 0 | P14: =SUMIF('บันทึกรายการ 63'!$B$822:$B$994,'Statement 63'!A14,'บันทึกรายการ 63'!$I$822:$I$994) -> 0 | Q14: =SUMIF('บันทึกรายการ 63'!$B$822:$B$994,'Statement 63'!A14,'บันทึกรายการ 63'!$J$822:$J$994) -> 0 | R14: =O14+Q14-P14 -> 0 | S14: =R14 -> 0
A15: 2131-02 | B15: ค่าเก็บขยะค้างจ่าย | C15: 3000 | D15: =SUMIF('บันทึกรายการ 63'!$B$7:$B$254,'Statement 63'!A15,'บันทึกรายการ 63'!$I$7:$I$254) -> 3000 | E15: =SUMIF('บันทึกรายการ 63'!$B$7:$B$254,'Statement 63'!A15,'บันทึกรายการ 63'!$J$7:$J$254) -> 3000 | F15: =C15+E15-D15 -> 3000 | G15: =SUMIF('บันทึกรายการ 63'!$B$257:$B$467,'Statement 63'!A15,'บันทึกรายการ 63'!$I$257:$I$467) -> 3000 | H15: =SUMIF('บันทึกรายการ 63'!$B$257:$B$467,'Statement 63'!A15,'บันทึกรายการ 63'!$J$257:$J$467) -> 3000 | I15: =F15+H15-G15 -> 3000 | J15: =SUMIF('บันทึกรายการ 63'!$B$471:$B$647,'Statement 63'!A15,'บันทึกรายการ 63'!$I$471:$I$647) -> 3000 | K15: =SUMIF('บันทึกรายการ 63'!$B$471:$B$647,'Statement 63'!A15,'บันทึกรายการ 63'!$J$471:$J$647) -> 3000 | L15: =I15+K15-J15 -> 3000 | M15: =SUMIF('บันทึกรายการ 63'!$B$649:$B$819,'Statement 63'!A15,'บันทึกรายการ 63'!$I$649:$I$819) -> 3000 | N15: =SUMIF('บันทึกรายการ 63'!$B$649:$B$819,'Statement 63'!A15,'บันทึกรายการ 63'!$J$649:$J$819) -> 3000 | O15: =L15+N15-M15 -> 3000 | P15: =SUMIF('บันทึกรายการ 63'!$B$822:$B$994,'Statement 63'!A15,'บันทึกรายการ 63'!$I$822:$I$994) -> 3000 | Q15: =SUMIF('บันทึกรายการ 63'!$B$822:$B$994,'Statement 63'!A15,'บันทึกรายการ 63'!$J$822:$J$994) -> 3000 | R15: =O15+Q15-P15 -> 3000 | S15: =R15 -> 3000
A16: 2131-03 | B16: ค่าบริการดูแลสระว่ายน้ำค้างจ่าย | C16: 8500 | D16: =SUMIF('บันทึกรายการ 63'!$B$7:$B$254,'Statement 63'!A16,'บันทึกรายการ 63'!$I$7:$I$254) -> 8500 | E16: =SUMIF('บันทึกรายการ 63'!$B$7:$B$254,'Statement 63'!A16,'บันทึกรายการ 63'!$J$7:$J$254) -> 7500 | F16: =C16+E16-D16 -> 7500 | G16: =SUMIF('บันทึกรายการ 63'!$B$257:$B$467,'Statement 63'!A16,'บันทึกรายการ 63'!$I$257:$I$467) -> 7500 | H16: =SUMIF('บันทึกรายการ 63'!$B$257:$B$467,'Statement 63'!A16,'บันทึกรายการ 63'!$J$257:$J$467) -> 7500 | I16: =F16+H16-G16 -> 7500 | J16: =SUMIF('บันทึกรายการ 63'!$B$471:$B$647,'Statement 63'!A16,'บันทึกรายการ 63'!$I$471:$I$647) -> 7500 | K16: =SUMIF('บันทึกรายการ 63'!$B$471:$B$647,'Statement 63'!A16,'บันทึกรายการ 63'!$J$471:$J$647) -> 7500 | L16: =I16+K16-J16 -> 7500 | M16: =SUMIF('บันทึกรายการ 63'!$B$649:$B$819,'Statement 63'!A16,'บันทึกรายการ 63'!$I$649:$I$819) -> 7500 | N16: =SUMIF('บันทึกรายการ 63'!$B$649:$B$819,'Statement 63'!A16,'บันทึกรายการ 63'!$J$649:$J$819) -> 0 | O16: =L16+N16-M16 -> 0 | P16: =SUMIF('บันทึกรายการ 63'!$B$822:$B$994,'Statement 63'!A16,'บันทึกรายการ 63'!$I$822:$I$994) -> 0 | Q16: =SUMIF('บันทึกรายการ 63'!$B$822:$B$994,'Statement 63'!A16,'บันทึกรายการ 63'!$J$822:$J$994) -> 0 | R16: =O16+Q16-P16 -> 0 | S16: =R16 -> 0
A17: 2131-04 | B17: ค่ารักษาความปลอดภัยค้างจ่าย | C17: 38233.18 | D17: =SUMIF('บันทึกรายการ 63'!$B$7:$B$254,'Statement 63'!A17,'บันทึกรายการ 63'!$I$7:$I$254) -> 38233.18 | E17: =SUMIF('บันทึกรายการ 63'!$B$7:$B$254,'Statement 63'!A17,'บันทึกรายการ 63'!$J$7:$J$254) -> 38233.18 | F17: =C17+E17-D17 -> 38233.18 | G17: =SUMIF('บันทึกรายการ 63'!$B$257:$B$467,'Statement 63'!A17,'บันทึกรายการ 63'!$I$257:$I$467) -> 38233.18 | H17: =SUMIF('บันทึกรายการ 63'!$B$257:$B$467,'Statement 63'!A17,'บันทึกรายการ 63'!$J$257:$J$467) -> 38814.32 | I17: =F17+H17-G17 -> 38814.32 | J17: =SUMIF('บันทึกรายการ 63'!$B$471:$B$647,'Statement 63'!A17,'บันทึกรายการ 63'!$I$471:$I$647) -> 38814.32 | K17: =SUMIF('บันทึกรายการ 63'!$B$471:$B$647,'Statement 63'!A17,'บันทึกรายการ 63'!$J$471:$J$647) -> 38814.32 | L17: =I17+K17-J17 -> 38814.32 | M17: =SUMIF('บันทึกรายการ 63'!$B$649:$B$819,'Statement 63'!A17,'บันทึกรายการ 63'!$I$649:$I$819) -> 38814.32 | N17: =SUMIF('บันทึกรายการ 63'!$B$649:$B$819,'Statement 63'!A17,'บันทึกรายการ 63'!$J$649:$J$819) -> 38814.32 | O17: =L17+N17-M17 -> 38814.32 | P17: =SUMIF('บันทึกรายการ 63'!$B$822:$B$994,'Statement 63'!A17,'บันทึกรายการ 63'!$I$822:$I$994) -> 38814.32 | Q17: =SUMIF('บันทึกรายการ 63'!$B$822:$B$994,'Statement 63'!A17,'บันทึกรายการ 63'!$J$822:$J$994) -> 38814.32 | R17: =O17+Q17-P17 -> 38814.32 | S17: =R17 -> 38814.32
A18: 2131-06 | B18: ค่าไฟฟ้าค้างจ่าย | C18: 3476.06 | D18: =SUMIF('บันทึกรายการ 63'!$B$7:$B$254,'Statement 63'!A18,'บันทึกรายการ 63'!$I$7:$I$254) -> 3476.06 | E18: =SUMIF('บันทึกรายการ 63'!$B$7:$B$254,'Statement 63'!A18,'บันทึกรายการ 63'!$J$7:$J$254) -> 4863.82 | F18: =C18+E18-D18 -> 4863.82 | G18: =SUMIF('บันทึกรายการ 63'!$B$257:$B$467,'Statement 63'!A18,'บันทึกรายการ 63'!$I$257:$I$467) -> 4863.82 | H18: =SUMIF('บันทึกรายการ 63'!$B$257:$B$467,'Statement 63'!A18,'บันทึกรายการ 63'!$J$257:$J$467) -> 5769.34 | I18: =F18+H18-G18 -> 5769.34 | J18: =SUMIF('บันทึกรายการ 63'!$B$471:$B$647,'Statement 63'!A18,'บันทึกรายการ 63'!$I$471:$I$647) -> 5769.34 | K18: =SUMIF('บันทึกรายการ 63'!$B$471:$B$647,'Statement 63'!A18,'บันทึกรายการ 63'!$J$471:$J$647) -> 6231.77 | L18: =I18+K18-J18 -> 6231.77 | M18: =SUMIF('บันทึกรายการ 63'!$B$649:$B$819,'Statement 63'!A18,'บันทึกรายการ 63'!$I$649:$I$819) -> 6231.77 | N18: =SUMIF('บันทึกรายการ 63'!$B$649:$B$819,'Statement 63'!A18,'บันทึกรายการ 63'!$J$649:$J$819) -> 5777.06 | O18: =L18+N18-M18 -> 5777.06 | P18: =SUMIF('บันทึกรายการ 63'!$B$822:$B$994,'Statement 63'!A18,'บันทึกรายการ 63'!$I$822:$I$994) -> 5777.06 | Q18: =SUMIF('บันทึกรายการ 63'!$B$822:$B$994,'Statement 63'!A18,'บันทึกรายการ 63'!$J$822:$J$994) -> 4930.58 | R18: =O18+Q18-P18 -> 4930.58 | S18: =R18 -> 4930.58
A19: 2131-08 | B19: ค่าดูแลส่วนกลางค้างจ่าย | C19: 15000 | D19: =SUMIF('บันทึกรายการ 63'!$B$7:$B$254,'Statement 63'!A19,'บันทึกรายการ 63'!$I$7:$I$254) -> 15000 | E19: =SUMIF('บันทึกรายการ 63'!$B$7:$B$254,'Statement 63'!A19,'บันทึกรายการ 63'!$J$7:$J$254) -> 15000 | F19: =C19+E19-D19 -> 15000 | G19: =SUMIF('บันทึกรายการ 63'!$B$257:$B$467,'Statement 63'!A19,'บันทึกรายการ 63'!$I$257:$I$467) -> 15000 | H19: =SUMIF('บันทึกรายการ 63'!$B$257:$B$467,'Statement 63'!A19,'บันทึกรายการ 63'!$J$257:$J$467) -> 15000 | I19: =F19+H19-G19 -> 15000 | J19: =SUMIF('บันทึกรายการ 63'!$B$471:$B$647,'Statement 63'!A19,'บันทึกรายการ 63'!$I$471:$I$647) -> 15000 | K19: =SUMIF('บันทึกรายการ 63'!$B$471:$B$647,'Statement 63'!A19,'บันทึกรายการ 63'!$J$471:$J$647) -> 15000 | L19: =I19+K19-J19 -> 15000 | M19: =SUMIF('บันทึกรายการ 63'!$B$649:$B$819,'Statement 63'!A19,'บันทึกรายการ 63'!$I$649:$I$819) -> 15000 | N19: =SUMIF('บันทึกรายการ 63'!$B$649:$B$819,'Statement 63'!A19,'บันทึกรายการ 63'!$J$649:$J$819) -> 15000 | O19: =L19+N19-M19 -> 15000 | P19: =SUMIF('บันทึกรายการ 63'!$B$822:$B$994,'Statement 63'!A19,'บันทึกรายการ 63'!$I$822:$I$994) -> 15000 | Q19: =SUMIF('บันทึกรายการ 63'!$B$822:$B$994,'Statement 63'!A19,'บันทึกรายการ 63'!$J$822:$J$994) -> 15000 | R19: =O19+Q19-P19 -> 15000 | S19: =R19 -> 15000
A20: 2131-09 | B20: ค่าดูแลส่วนกลางรับล่วงหน้า | C20: 600 | D20: =SUMIF('บันทึกรายการ 63'!$B$7:$B$254,'Statement 63'!A20,'บันทึกรายการ 63'!$I$7:$I$254) -> 0 | E20: =SUMIF('บันทึกรายการ 63'!$B$7:$B$254,'Statement 63'!A20,'บันทึกรายการ 63'!$J$7:$J$254) -> 0 | F20: =C20+E20-D20 -> 600 | G20: =SUMIF('บันทึกรายการ 63'!$B$257:$B$467,'Statement 63'!A20,'บันทึกรายการ 63'!$I$257:$I$467) -> 0 | H20: =SUMIF('บันทึกรายการ 63'!$B$257:$B$467,'Statement 63'!A20,'บันทึกรายการ 63'!$J$257:$J$467) -> 200 | I20: =F20+H20-G20 -> 800 | J20: =SUMIF('บันทึกรายการ 63'!$B$471:$B$647,'Statement 63'!A20,'บันทึกรายการ 63'!$I$471:$I$647) -> 0 | K20: =SUMIF('บันทึกรายการ 63'!$B$471:$B$647,'Statement 63'!A20,'บันทึกรายการ 63'!$J$471:$J$647) -> 0 | L20: =I20+K20-J20 -> 800 | M20: =SUMIF('บันทึกรายการ 63'!$B$649:$B$819,'Statement 63'!A20,'บันทึกรายการ 63'!$I$649:$I$819) -> 0 | N20: =SUMIF('บันทึกรายการ 63'!$B$649:$B$819,'Statement 63'!A20,'บันทึกรายการ 63'!$J$649:$J$819) -> 0 | O20: =L20+N20-M20 -> 800 | P20: =SUMIF('บันทึกรายการ 63'!$B$822:$B$994,'Statement 63'!A20,'บันทึกรายการ 63'!$I$822:$I$994) -> 0 | Q20: =SUMIF('บันทึกรายการ 63'!$B$822:$B$994,'Statement 63'!A20,'บันทึกรายการ 63'!$J$822:$J$994) -> 0 | R20: =O20+Q20-P20 -> 800 | S20: =R20 -> 800
A21: 2131-11 | B21: ค่าบริการทำบัญชีค้างจ่าย | C21: 32125 | D21: =SUMIF('บันทึกรายการ 63'!$B$7:$B$254,'Statement 63'!A21,'บันทึกรายการ 63'!$I$7:$I$254) -> 0 | E21: =SUMIF('บันทึกรายการ 63'!$B$7:$B$254,'Statement 63'!A21,'บันทึกรายการ 63'!$J$7:$J$254) -> 0 | F21: =C21+E21-D21 -> 32125 | G21: =SUMIF('บันทึกรายการ 63'!$B$257:$B$467,'Statement 63'!A21,'บันทึกรายการ 63'!$I$257:$I$467) -> 30125 | H21: =SUMIF('บันทึกรายการ 63'!$B$257:$B$467,'Statement 63'!A21,'บันทึกรายการ 63'!$J$257:$J$467) -> 0 | I21: =F21+H21-G21 -> 2000 | J21: =SUMIF('บันทึกรายการ 63'!$B$471:$B$647,'Statement 63'!A21,'บันทึกรายการ 63'!$I$471:$I$647) -> 2000 | K21: =SUMIF('บันทึกรายการ 63'!$B$471:$B$647,'Statement 63'!A21,'บันทึกรายการ 63'!$J$471:$J$647) -> 0 | L21: =I21+K21-J21 -> 0 | M21: =SUMIF('บันทึกรายการ 63'!$B$649:$B$819,'Statement 63'!A21,'บันทึกรายการ 63'!$I$649:$I$819) -> 0 | N21: =SUMIF('บันทึกรายการ 63'!$B$649:$B$819,'Statement 63'!A21,'บันทึกรายการ 63'!$J$649:$J$819) -> 0 | O21: =L21+N21-M21 -> 0 | P21: =SUMIF('บันทึกรายการ 63'!$B$822:$B$994,'Statement 63'!A21,'บันทึกรายการ 63'!$I$822:$I$994) -> 0 | Q21: =SUMIF('บันทึกรายการ 63'!$B$822:$B$994,'Statement 63'!A21,'บันทึกรายการ 63'!$J$822:$J$994) -> 0 | R21: =O21+Q21-P21 -> 0 | S21: =R21 -> 0
A22: 2133-01 | B22: รายได้ค่าส่วนกลางไม่ทราบชือ | C22: 34200 | D22: =SUMIF('บันทึกรายการ 63'!$B$7:$B$254,'Statement 63'!A22,'บันทึกรายการ 63'!$I$7:$I$254) -> 0 | E22: =SUMIF('บันทึกรายการ 63'!$B$7:$B$254,'Statement 63'!A22,'บันทึกรายการ 63'!$J$7:$J$254) -> 600 | F22: =C22+E22-D22 -> 34800 | G22: =SUMIF('บันทึกรายการ 63'!$B$257:$B$467,'Statement 63'!A22,'บันทึกรายการ 63'!$I$257:$I$467) -> 0 | H22: =SUMIF('บันทึกรายการ 63'!$B$257:$B$467,'Statement 63'!A22,'บันทึกรายการ 63'!$J$257:$J$467) -> 4200 | I22: =F22+H22-G22 -> 39000 | J22: =SUMIF('บันทึกรายการ 63'!$B$471:$B$647,'Statement 63'!A22,'บันทึกรายการ 63'!$I$471:$I$647) -> 0 | K22: =SUMIF('บันทึกรายการ 63'!$B$471:$B$647,'Statement 63'!A22,'บันทึกรายการ 63'!$J$471:$J$647) -> 600 | L22: =I22+K22-J22 -> 39600 | M22: =SUMIF('บันทึกรายการ 63'!$B$649:$B$819,'Statement 63'!A22,'บันทึกรายการ 63'!$I$649:$I$819) -> 0 | N22: =SUMIF('บันทึกรายการ 63'!$B$649:$B$819,'Statement 63'!A22,'บันทึกรายการ 63'!$J$649:$J$819) -> 3000 | O22: =L22+N22-M22 -> 42600 | P22: =SUMIF('บันทึกรายการ 63'!$B$822:$B$994,'Statement 63'!A22,'บันทึกรายการ 63'!$I$822:$I$994) -> 0 | Q22: =SUMIF('บันทึกรายการ 63'!$B$822:$B$994,'Statement 63'!A22,'บันทึกรายการ 63'!$J$822:$J$994) -> 10800 | R22: =O22+Q22-P22 -> 53400 | S22: =R22 -> 53400
A23: 2133-02 | B23: ค่าส่วนกลางรับล่วงหน้า | C23: 8100 | D23: =SUMIF('บันทึกรายการ 63'!$B$7:$B$254,'Statement 63'!A23,'บันทึกรายการ 63'!$I$7:$I$254) -> 0 | E23: =SUMIF('บันทึกรายการ 63'!$B$7:$B$254,'Statement 63'!A23,'บันทึกรายการ 63'!$J$7:$J$254) -> 0 | F23: =C23+E23-D23 -> 8100 | G23: =SUMIF('บันทึกรายการ 63'!$B$257:$B$467,'Statement 63'!A23,'บันทึกรายการ 63'!$I$257:$I$467) -> 0 | H23: =SUMIF('บันทึกรายการ 63'!$B$257:$B$467,'Statement 63'!A23,'บันทึกรายการ 63'!$J$257:$J$467) -> 0 | I23: =F23+H23-G23 -> 8100 | J23: =SUMIF('บันทึกรายการ 63'!$B$471:$B$647,'Statement 63'!A23,'บันทึกรายการ 63'!$I$471:$I$647) -> 0 | K23: =SUMIF('บันทึกรายการ 63'!$B$471:$B$647,'Statement 63'!A23,'บันทึกรายการ 63'!$J$471:$J$647) -> 0 | L23: =I23+K23-J23 -> 8100 | M23: =SUMIF('บันทึกรายการ 63'!$B$649:$B$819,'Statement 63'!A23,'บันทึกรายการ 63'!$I$649:$I$819) -> 0 | N23: =SUMIF('บันทึกรายการ 63'!$B$649:$B$819,'Statement 63'!A23,'บันทึกรายการ 63'!$J$649:$J$819) -> 0 | O23: =L23+N23-M23 -> 8100 | P23: =SUMIF('บันทึกรายการ 63'!$B$822:$B$994,'Statement 63'!A23,'บันทึกรายการ 63'!$I$822:$I$994) -> 0 | Q23: =SUMIF('บันทึกรายการ 63'!$B$822:$B$994,'Statement 63'!A23,'บันทึกรายการ 63'!$J$822:$J$994) -> 0 | R23: =O23+Q23-P23 -> 8100 | S23: =R23 -> 8100
A24: 3100-00 | B24: เงินสนับสนุนจากโครงการ | C24: 1057329 | D24: =SUMIF('บันทึกรายการ 63'!$B$7:$B$254,'Statement 63'!A24,'บันทึกรายการ 63'!$I$7:$I$254) -> 0 | E24: =SUMIF('บันทึกรายการ 63'!$B$7:$B$254,'Statement 63'!A24,'บันทึกรายการ 63'!$J$7:$J$254) -> 0 | F24: =C24+E24-D24 -> 1057329 | G24: =SUMIF('บันทึกรายการ 63'!$B$257:$B$467,'Statement 63'!A24,'บันทึกรายการ 63'!$I$257:$I$467) -> 0 | H24: =SUMIF('บันทึกรายการ 63'!$B$257:$B$467,'Statement 63'!A24,'บันทึกรายการ 63'!$J$257:$J$467) -> 0 | I24: =F24+H24-G24 -> 1057329 | J24: =SUMIF('บันทึกรายการ 63'!$B$471:$B$647,'Statement 63'!A24,'บันทึกรายการ 63'!$I$471:$I$647) -> 0 | K24: =SUMIF('บันทึกรายการ 63'!$B$471:$B$647,'Statement 63'!A24,'บันทึกรายการ 63'!$J$471:$J$647) -> 0 | L24: =I24+K24-J24 -> 1057329 | M24: =SUMIF('บันทึกรายการ 63'!$B$649:$B$819,'Statement 63'!A24,'บันทึกรายการ 63'!$I$649:$I$819) -> 0 | N24: =SUMIF('บันทึกรายการ 63'!$B$649:$B$819,'Statement 63'!A24,'บันทึกรายการ 63'!$J$649:$J$819) -> 0 | O24: =L24+N24-M24 -> 1057329 | P24: =SUMIF('บันทึกรายการ 63'!$B$822:$B$994,'Statement 63'!A24,'บันทึกรายการ 63'!$I$822:$I$994) -> 0 | Q24: =SUMIF('บันทึกรายการ 63'!$B$822:$B$994,'Statement 63'!A24,'บันทึกรายการ 63'!$J$822:$J$994) -> 0 | R24: =O24+Q24-P24 -> 1057329 | S24: =R24 -> 1057329
A25: 3200-00 | B25: รายรับมากกว่ารายจ่ายต้นงวด | C25: 135970.06 | D25: =SUMIF('บันทึกรายการ 63'!$B$7:$B$254,'Statement 63'!A25,'บันทึกรายการ 63'!$I$7:$I$254) -> 0 | E25: =SUMIF('บันทึกรายการ 63'!$B$7:$B$254,'Statement 63'!A25,'บันทึกรายการ 63'!$J$7:$J$254) -> 0 | F25: =C25+E25-D25+F49 -> 200630.14 | G25: =SUMIF('บันทึกรายการ 63'!$B$257:$B$467,'Statement 63'!A25,'บันทึกรายการ 63'!$I$257:$I$467) -> 0 | H25: =SUMIF('บันทึกรายการ 63'!$B$257:$B$467,'Statement 63'!A25,'บันทึกรายการ 63'!$J$257:$J$467) -> 0 | I25: =F25+H25-G25+I49 -> 217151.17 | J25: =SUMIF('บันทึกรายการ 63'!$B$471:$B$647,'Statement 63'!A25,'บันทึกรายการ 63'!$I$471:$I$647) -> 0 | K25: =SUMIF('บันทึกรายการ 63'!$B$471:$B$647,'Statement 63'!A25,'บันทึกรายการ 63'!$J$471:$J$647) -> 0 | L25: =I25+K25-J25+L49 -> 183291.2 | M25: =SUMIF('บันทึกรายการ 63'!$B$649:$B$819,'Statement 63'!A25,'บันทึกรายการ 63'!$I$649:$I$819) -> 0 | N25: =SUMIF('บันทึกรายการ 63'!$B$649:$B$819,'Statement 63'!A25,'บันทึกรายการ 63'!$J$649:$J$819) -> 0 | O25: =L25+N25-M25+O49 -> 171794.23 | P25: =SUMIF('บันทึกรายการ 63'!$B$822:$B$994,'Statement 63'!A25,'บันทึกรายการ 63'!$I$822:$I$994) -> 0 | Q25: =SUMIF('บันทึกรายการ 63'!$B$822:$B$994,'Statement 63'!A25,'บันทึกรายการ 63'!$J$822:$J$994) -> 0 | R25: =O25+Q25-P25+R49 -> 143391.49 | S25: =R25 -> 143391.49
B26: รวมหนี้สินและส่วนของหมู่บ้าน | C26: =SUM(C14:C25) -> 1336533.3 | D26: =SUM(D14:D25) -> 68209.24 | E26: =SUM(E14:E25) -> 69197 | F26: =SUM(F14:F25) -> 1402181.1 | G26: =SUM(G14:G25) -> 98722 | H26: =SUM(H14:H25) -> 74483.66 | I26: =SUM(I14:I25) -> 1394463.8 | J26: =SUM(J14:J25) -> 72083.66 | ... S26: =SUM(S14:S25) -> 1324765.4
C27: =C26-C12 -> 0 | D27: =D26-D12 -> -167802.55 | E27: =E26-E12 -> -101166.95 | F27: =F26-F12 -> 0 | G27: =G26-G12 -> -233282.69 | H27: =H26-H12 -> -265238.34 | I27: =I26-I12 -> 0 | J27: =J26-J12 -> 14077.54 | ... S27: =S26-S12 -> 0
B30: รายงาน รายรับรายจ่าย
A31: 4100-01 | B31: รายรับค่าส่วนกลาง | D31: =SUMIF('บันทึกรายการ 63'!$B$7:$B$254,'Statement 63'!A31,'บันทึกรายการ 63'!$I$7:$I$254) -> 7200 | E31: =SUMIF('บันทึกรายการ 63'!$B$7:$B$254,'Statement 63'!A31,'บันทึกรายการ 63'!$J$7:$J$254) -> 207809.48 | F31: =E31-D31 -> 200609.48 | G31: =SUMIF('บันทึกรายการ 63'!$B$257:$B$467,'Statement 63'!A31,'บันทึกรายการ 63'!$I$257:$I$467) -> 0 | H31: =SUMIF('บันทึกรายการ 63'!$B$257:$B$467,'Statement 63'!A31,'บันทึกรายการ 63'!$J$257:$J$467) -> 87404.69 | I31: =H31-G31 -> 87404.69 | J31: =SUMIF('บันทึกรายการ 63'!$B$471:$B$647,'Statement 63'!A31,'บันทึกรายการ 63'!$I$471:$I$647) -> 0 | K31: =SUMIF('บันทึกรายการ 63'!$B$471:$B$647,'Statement 63'!A31,'บันทึกรายการ 63'!$J$471:$J$647) -> 49604.12 | L31: =K31-J31 -> 49604.12 | M31: =SUMIF('บันทึกรายการ 63'!$B$649:$B$819,'Statement 63'!A31,'บันทึกรายการ 63'!$I$649:$I$819) -> 0 | N31: =SUMIF('บันทึกรายการ 63'!$B$649:$B$819,'Statement 63'!A31,'บันทึกรายการ 63'!$J$649:$J$819) -> 52806.41 | O31: =N31-M31 -> 52806.41 | P31: =SUMIF('บันทึกรายการ 63'!$B$822:$B$994,'Statement 63'!A31,'บันทึกรายการ 63'!$I$822:$I$994) -> 0 | Q31: =SUMIF('บันทึกรายการ 63'!$B$822:$B$994,'Statement 63'!A31,'บันทึกรายการ 63'!$J$822:$J$994) -> 48004.46 | R31: =Q31-P31 -> 48004.46 | S31: =F31+I31+L31+O31+R31 -> 438429.16
A32: 4100-02 | B32: รายรับอื่นๆ | D32: =SUMIF('บันทึกรายการ 63'!$B$7:$B$254,'Statement 63'!A32,'บันทึกรายการ 63'!$I$7:$I$254) -> 0 | E32: =SUMIF('บันทึกรายการ 63'!$B$7:$B$254,'Statement 63'!A32,'บันทึกรายการ 63'!$J$7:$J$254) -> 0 | F32: =E32-D32 -> 0 | G32: =SUMIF('บันทึกรายการ 63'!$B$257:$B$467,'Statement 63'!A32,'บันทึกรายการ 63'!$I$257:$I$467) -> 0 | H32: =SUMIF('บันทึกรายการ 63'!$B$257:$B$467,'Statement 63'!A32,'บันทึกรายการ 63'!$J$257:$J$467) -> 0 | I32: =H32-G32 -> 0 | J32: =SUMIF('บันทึกรายการ 63'!$B$471:$B$647,'Statement 63'!A32,'บันทึกรายการ 63'!$I$471:$I$647) -> 0 | K32: =SUMIF('บันทึกรายการ 63'!$B$471:$B$647,'Statement 63'!A32,'บันทึกรายการ 63'!$J$471:$J$647) -> 0 | L32: =K32-J32 -> 0 | M32: =SUMIF('บันทึกรายการ 63'!$B$649:$B$819,'Statement 63'!A32,'บันทึกรายการ 63'!$I$649:$I$819) -> 0 | N32: =SUMIF('บันทึกรายการ 63'!$B$649:$B$819,'Statement 63'!A32,'บันทึกรายการ 63'!$J$649:$J$819) -> 0 | O32: =N32-M32 -> 0 | P32: =SUMIF('บันทึกรายการ 63'!$B$822:$B$994,'Statement 63'!A32,'บันทึกรายการ 63'!$I$822:$I$994) -> 0 | Q32: =SUMIF('บันทึกรายการ 63'!$B$822:$B$994,'Statement 63'!A32,'บันทึกรายการ 63'!$J$822:$J$994) -> 0 | R32: =Q32-P32 -> 0 | S32: =F32+I32+L32+O32+R32 -> 0
A33: 4200-01 | B33: ดอกเบี้ยรับ | D33: =SUMIF('บันทึกรายการ 63'!$B$7:$B$254,'Statement 63'!A33,'บันทึกรายการ 63'!$I$7:$I$254) -> 0 | E33: =SUMIF('บันทึกรายการ 63'!$B$7:$B$254,'Statement 63'!A33,'บันทึกรายการ 63'!$J$7:$J$254) -> 0 | F33: =E33-D33 -> 0 | G33: =SUMIF('บันทึกรายการ 63'!$B$257:$B$467,'Statement 63'!A33,'บันทึกรายการ 63'!$I$257:$I$467) -> 0 | H33: =SUMIF('บันทึกรายการ 63'!$B$257:$B$467,'Statement 63'!A33,'บันทึกรายการ 63'!$J$257:$J$467) -> 0 | I33: =H33-G33 -> 0 | J33: =SUMIF('บันทึกรายการ 63'!$B$471:$B$647,'Statement 63'!A33,'บันทึกรายการ 63'!$I$471:$I$647) -> 0 | K33: =SUMIF('บันทึกรายการ 63'!$B$471:$B$647,'Statement 63'!A33,'บันทึกรายการ 63'!$J$471:$J$647) -> 0 | L33: =K33-J33 -> 0 | M33: =SUMIF('บันทึกรายการ 63'!$B$649:$B$819,'Statement 63'!A33,'บันทึกรายการ 63'!$I$649:$I$819) -> 0 | N33: =SUMIF('บันทึกรายการ 63'!$B$649:$B$819,'Statement 63'!A33,'บันทึกรายการ 63'!$J$649:$J$819) -> 0 | O33: =N33-M33 -> 0 | P33: =SUMIF('บันทึกรายการ 63'!$B$822:$B$994,'Statement 63'!A33,'บันทึกรายการ 63'!$I$822:$I$994) -> 0 | Q33: =SUMIF('บันทึกรายการ 63'!$B$822:$B$994,'Statement 63'!A33,'บันทึกรายการ 63'!$J$822:$J$994) -> 0 | R33: =Q33-P33 -> 0 | S33: =F33+I33+L33+O33+R33 -> 0
C34: =SUM(C31:C33) -> 0 | D34: =SUM(D31:D33) -> 7200 | E34: =SUM(E31:E33) -> 207809.48 | F34: =SUM(F31:F33) -> 200609.48 | G34: =SUM(G31:G33) -> 0 | H34: =SUM(H31:H33) -> 87404.69 | I34: =SUM(I31:I33) -> 87404.69 | J34: =SUM(J31:J33) -> 0 | ... S34: =SUM(S31:S33) -> 438429.16
A36: 5110-09 | B36: ส่วนลดรับ | D36: =SUMIF('บันทึกรายการ 63'!$B$7:$B$254,'Statement 63'!A36,'บันทึกรายการ 63'!$I$7:$I$254) -> 0 | E36: =SUMIF('บันทึกรายการ 63'!$B$7:$B$254,'Statement 63'!A36,'บันทึกรายการ 63'!$J$7:$J$254) -> 0 | F36: =D36-E36 -> 0 | G36: =SUMIF('บันทึกรายการ 63'!$B$257:$B$467,'Statement 63'!A36,'บันทึกรายการ 63'!$I$257:$I$467) -> 0 | H36: =SUMIF('บันทึกรายการ 63'!$B$257:$B$467,'Statement 63'!A36,'บันทึกรายการ 63'!$J$257:$J$467) -> 0 | I36: =G36-H36 -> 0 | J36: =SUMIF('บันทึกรายการ 63'!$B$471:$B$647,'Statement 63'!A36,'บันทึกรายการ 63'!$I$471:$I$647) -> 0 | K36: =SUMIF('บันทึกรายการ 63'!$B$471:$B$647,'Statement 63'!A36,'บันทึกรายการ 63'!$J$471:$J$647) -> 0 | L36: =J36-K36 -> 0 | M36: =SUMIF('บันทึกรายการ 63'!$B$649:$B$819,'Statement 63'!A36,'บันทึกรายการ 63'!$I$649:$I$819) -> 0 | N36: =SUMIF('บันทึกรายการ 63'!$B$649:$B$819,'Statement 63'!A36,'บันทึกรายการ 63'!$J$649:$J$819) -> 0 | O36: =M36-N36 -> 0 | P36: =SUMIF('บันทึกรายการ 63'!$B$822:$B$994,'Statement 63'!A36,'บันทึกรายการ 63'!$I$822:$I$994) -> 0 | Q36: =SUMIF('บันทึกรายการ 63'!$B$822:$B$994,'Statement 63'!A36,'บันทึกรายการ 63'!$J$822:$J$994) -> 0 | R36: =P36-Q36 -> 0 | S36: =F36+I36+L36+O36+R36 -> 0
A37: 5320-02 | B37: ค่าอะไหล่ซ่อมบำรุงและค่าซ่อมแซมอื่นๆ | D37: =SUMIF('บันทึกรายการ 63'!$B$7:$B$254,'Statement 63'!A37,'บันทึกรายการ 63'!$I$7:$I$254) -> 67352.4 | E37: =SUMIF('บันทึกรายการ 63'!$B$7:$B$254,'Statement 63'!A37,'บันทึกรายการ 63'!$J$7:$J$254) -> 0 | F37: =D37-E37 -> 67352.4 | G37: =SUMIF('บันทึกรายการ 63'!$B$257:$B$467,'Statement 63'!A37,'บันทึกรายการ 63'!$I$257:$I$467) -> 0 | H37: =SUMIF('บันทึกรายการ 63'!$B$257:$B$467,'Statement 63'!A37,'บันทึกรายการ 63'!$J$257:$J$467) -> 0 | I37: =G37-H37 -> 0 | J37: =SUMIF('บันทึกรายการ 63'!$B$471:$B$647,'Statement 63'!A37,'บันทึกรายการ 63'!$I$471:$I$647) -> 0 | K37: =SUMIF('บันทึกรายการ 63'!$B$471:$B$647,'Statement 63'!A37,'บันทึกรายการ 63'!$J$471:$J$647) -> 0 | L37: =J37-K37 -> 0 | M37: =SUMIF('บันทึกรายการ 63'!$B$649:$B$819,'Statement 63'!A37,'บันทึกรายการ 63'!$I$649:$I$819) -> 1712 | N37: =SUMIF('บันทึกรายการ 63'!$B$649:$B$819,'Statement 63'!A37,'บันทึกรายการ 63'!$J$649:$J$819) -> 0 | O37: =M37-N37 -> 1712 | P37: =SUMIF('บันทึกรายการ 63'!$B$822:$B$994,'Statement 63'!A37,'บันทึกรายการ 63'!$I$822:$I$994) -> 14662.3 | Q37: =SUMIF('บันทึกรายการ 63'!$B$822:$B$994,'Statement 63'!A37,'บันทึกรายการ 63'!$J$822:$J$994) -> 0 | R37: =P37-Q37 -> 14662.3 | S37: =F37+I37+L37+O37+R37 -> 83726.7
A38: 5320-03 | B38: วัสดุสิ้นเปลือง | D38: =SUMIF('บันทึกรายการ 63'!$B$7:$B$254,'Statement 63'!A38,'บันทึกรายการ 63'!$I$7:$I$254) -> 0 | E38: =SUMIF('บันทึกรายการ 63'!$B$7:$B$254,'Statement 63'!A38,'บันทึกรายการ 63'!$J$7:$J$254) -> 0 | F38: =D38-E38 -> 0 | G38: =SUMIF('บันทึกรายการ 63'!$B$257:$B$467,'Statement 63'!A38,'บันทึกรายการ 63'!$I$257:$I$467) -> 800 | H38: =SUMIF('บันทึกรายการ 63'!$B$257:$B$467,'Statement 63'!A38,'บันทึกรายการ 63'!$J$257:$J$467) -> 0 | I38: =G38-H38 -> 800 | J38: =SUMIF('บันทึกรายการ 63'!$B$471:$B$647,'Statement 63'!A38,'บันทึกรายการ 63'!$I$471:$I$647) -> 920 | K38: =SUMIF('บันทึกรายการ 63'!$B$471:$B$647,'Statement 63'!A38,'บันทึกรายการ 63'!$J$471:$J$647) -> 0 | L38: =J38-K38 -> 920 | M38: =SUMIF('บันทึกรายการ 63'!$B$649:$B$819,'Statement 63'!A38,'บันทึกรายการ 63'!$I$649:$I$819) -> 0 | N38: =SUMIF('บันทึกรายการ 63'!$B$649:$B$819,'Statement 63'!A38,'บันทึกรายการ 63'!$J$649:$J$819) -> 0 | O38: =M38-N38 -> 0 | P38: =SUMIF('บันทึกรายการ 63'!$B$822:$B$994,'Statement 63'!A38,'บันทึกรายการ 63'!$I$822:$I$994) -> 0 | Q38: =SUMIF('บันทึกรายการ 63'!$B$822:$B$994,'Statement 63'!A38,'บันทึกรายการ 63'!$J$822:$J$994) -> 0 | R38: =P38-Q38 -> 0 | S38: =F38+I38+L38+O38+R38 -> 1720
A39: 5320-05 | B39: ค่าดูแลส่วนกลาง | D39: =SUMIF('บันทึกรายการ 63'!$B$7:$B$254,'Statement 63'!A39,'บันทึกรายการ 63'!$I$7:$I$254) -> 15000 | E39: =SUMIF('บันทึกรายการ 63'!$B$7:$B$254,'Statement 63'!A39,'บันทึกรายการ 63'!$J$7:$J$254) -> 0 | F39: =D39-E39 -> 15000 | G39: =SUMIF('บันทึกรายการ 63'!$B$257:$B$467,'Statement 63'!A39,'บันทึกรายการ 63'!$I$257:$I$467) -> 15000 | H39: =SUMIF('บันทึกรายการ 63'!$B$257:$B$467,'Statement 63'!A39,'บันทึกรายการ 63'!$J$257:$J$467) -> 0 | I39: =G39-H39 -> 15000 | J39: =SUMIF('บันทึกรายการ 63'!$B$471:$B$647,'Statement 63'!A39,'บันทึกรายการ 63'!$I$471:$I$647) -> 15000 | K39: =SUMIF('บันทึกรายการ 63'!$B$471:$B$647,'Statement 63'!A39,'บันทึกรายการ 63'!$J$471:$J$647) -> 0 | L39: =J39-K39 -> 15000 | M39: =SUMIF('บันทึกรายการ 63'!$B$649:$B$819,'Statement 63'!A39,'บันทึกรายการ 63'!$I$649:$I$819) -> 15000 | N39: =SUMIF('บันทึกรายการ 63'!$B$649:$B$819,'Statement 63'!A39,'บันทึกรายการ 63'!$J$649:$J$819) -> 0 | O39: =M39-N39 -> 15000 | P39: =SUMIF('บันทึกรายการ 63'!$B$822:$B$994,'Statement 63'!A39,'บันทึกรายการ 63'!$I$822:$I$994) -> 15000 | Q39: =SUMIF('บันทึกรายการ 63'!$B$822:$B$994,'Statement 63'!A39,'บันทึกรายการ 63'!$J$822:$J$994) -> 0 | R39: =P39-Q39 -> 15000 | S39: =F39+I39+L39+O39+R39 -> 75000
A40: 5320-06 | B40: ค่ารักษาความปลอดภัย | D40: =SUMIF('บันทึกรายการ 63'!$B$7:$B$254,'Statement 63'!A40,'บันทึกรายการ 63'!$I$7:$I$254) -> 38233.18 | E40: =SUMIF('บันทึกรายการ 63'!$B$7:$B$254,'Statement 63'!A40,'บันทึกรายการ 63'!$J$7:$J$254) -> 0 | F40: =D40-E40 -> 38233.18 | G40: =SUMIF('บันทึกรายการ 63'!$B$257:$B$467,'Statement 63'!A40,'บันทึกรายการ 63'!$I$257:$I$467) -> 38814.32 | H40: =SUMIF('บันทึกรายการ 63'!$B$257:$B$467,'Statement 63'!A40,'บันทึกรายการ 63'!$J$257:$J$467) -> 0 | I40: =G40-H40 -> 38814.32 | J40: =SUMIF('บันทึกรายการ 63'!$B$471:$B$647,'Statement 63'!A40,'บันทึกรายการ 63'!$I$471:$I$647) -> 38814.32 | K40: =SUMIF('บันทึกรายการ 63'!$B$471:$B$647,'Statement 63'!A40,'บันทึกรายการ 63'!$J$471:$J$647) -> 0 | L40: =J40-K40 -> 38814.32 | M40: =SUMIF('บันทึกรายการ 63'!$B$649:$B$819,'Statement 63'!A40,'บันทึกรายการ 63'!$I$649:$I$819) -> 38814.32 | N40: =SUMIF('บันทึกรายการ 63'!$B$649:$B$819,'Statement 63'!A40,'บันทึกรายการ 63'!$J$649:$J$819) -> 0 | O40: =M40-N40 -> 38814.32 | P40: =SUMIF('บันทึกรายการ 63'!$B$822:$B$994,'Statement 63'!A40,'บันทึกรายการ 63'!$I$822:$I$994) -> 38814.32 | Q40: =SUMIF('บันทึกรายการ 63'!$B$822:$B$994,'Statement 63'!A40,'บันทึกรายการ 63'!$J$822:$J$994) -> 0 | R40: =P40-Q40 -> 38814.32 | S40: =F40+I40+L40+O40+R40 -> 193490.46
A41: 5320-07 | B41: ค่าเก็บขยะ | D41: =SUMIF('บันทึกรายการ 63'!$B$7:$B$254,'Statement 63'!A41,'บันทึกรายการ 63'!$I$7:$I$254) -> 3000 | E41: =SUMIF('บันทึกรายการ 63'!$B$7:$B$254,'Statement 63'!A41,'บันทึกรายการ 63'!$J$7:$J$254) -> 0 | F41: =D41-E41 -> 3000 | G41: =SUMIF('บันทึกรายการ 63'!$B$257:$B$467,'Statement 63'!A41,'บันทึกรายการ 63'!$I$257:$I$467) -> 3000 | H41: =SUMIF('บันทึกรายการ 63'!$B$257:$B$467,'Statement 63'!A41,'บันทึกรายการ 63'!$J$257:$J$467) -> 0 | I41: =G41-H41 -> 3000 | J41: =SUMIF('บันทึกรายการ 63'!$B$471:$B$647,'Statement 63'!A41,'บันทึกรายการ 63'!$I$471:$I$647) -> 3000 | K41: =SUMIF('บันทึกรายการ 63'!$B$471:$B$647,'Statement 63'!A41,'บันทึกรายการ 63'!$J$471:$J$647) -> 0 | L41: =J41-K41 -> 3000 | M41: =SUMIF('บันทึกรายการ 63'!$B$649:$B$819,'Statement 63'!A41,'บันทึกรายการ 63'!$I$649:$I$819) -> 3000 | N41: =SUMIF('บันทึกรายการ 63'!$B$649:$B$819,'Statement 63'!A41,'บันทึกรายการ 63'!$J$649:$J$819) -> 0 | O41: =M41-N41 -> 3000 | P41: =SUMIF('บันทึกรายการ 63'!$B$822:$B$994,'Statement 63'!A41,'บันทึกรายการ 63'!$I$822:$I$994) -> 3000 | Q41: =SUMIF('บันทึกรายการ 63'!$B$822:$B$994,'Statement 63'!A41,'บันทึกรายการ 63'!$J$822:$J$994) -> 0 | R41: =P41-Q41 -> 3000 | S41: =F41+I41+L41+O41+R41 -> 15000
A42: 5320-10 | B42: ค่าบริการดูแลสระว่ายน้ำ | D42: =SUMIF('บันทึกรายการ 63'!$B$7:$B$254,'Statement 63'!A42,'บันทึกรายการ 63'!$I$7:$I$254) -> 7500 | E42: =SUMIF('บันทึกรายการ 63'!$B$7:$B$254,'Statement 63'!A42,'บันทึกรายการ 63'!$J$7:$J$254) -> 0 | F42: =D42-E42 -> 7500 | G42: =SUMIF('บันทึกรายการ 63'!$B$257:$B$467,'Statement 63'!A42,'บันทึกรายการ 63'!$I$257:$I$467) -> 7500 | H42: =SUMIF('บันทึกรายการ 63'!$B$257:$B$467,'Statement 63'!A42,'บันทึกรายการ 63'!$J$257:$J$467) -> 0 | I42: =G42-H42 -> 7500 | J42: =SUMIF('บันทึกรายการ 63'!$B$471:$B$647,'Statement 63'!A42,'บันทึกรายการ 63'!$I$471:$I$647) -> 7500 | K42: =SUMIF('บันทึกรายการ 63'!$B$471:$B$647,'Statement 63'!A42,'บันทึกรายการ 63'!$J$471:$J$647) -> 0 | L42: =J42-K42 -> 7500 | M42: =SUMIF('บันทึกรายการ 63'!$B$649:$B$819,'Statement 63'!A42,'บันทึกรายการ 63'!$I$649:$I$819) -> 0 | N42: =SUMIF('บันทึกรายการ 63'!$B$649:$B$819,'Statement 63'!A42,'บันทึกรายการ 63'!$J$649:$J$819) -> 0 | O42: =M42-N42 -> 0 | P42: =SUMIF('บันทึกรายการ 63'!$B$822:$B$994,'Statement 63'!A42,'บันทึกรายการ 63'!$I$822:$I$994) -> 0 | Q42: =SUMIF('บันทึกรายการ 63'!$B$822:$B$994,'Statement 63'!A42,'บันทึกรายการ 63'!$J$822:$J$994) -> 0 | R42: =P42-Q42 -> 0 | S42: =F42+I42+L42+O42+R42 -> 22500
A43: 5330-01 | B43: ค่าไฟฟ้า | D43: =SUMIF('บันทึกรายการ 63'!$B$7:$B$254,'Statement 63'!A43,'บันทึกรายการ 63'!$I$7:$I$254) -> 4863.82 | E43: =SUMIF('บันทึกรายการ 63'!$B$7:$B$254,'Statement 63'!A43,'บันทึกรายการ 63'!$J$7:$J$254) -> 0 | F43: =D43-E43 -> 4863.82 | G43: =SUMIF('บันทึกรายการ 63'!$B$257:$B$467,'Statement 63'!A43,'บันทึกรายการ 63'!$I$257:$I$467) -> 5769.34 | H43: =SUMIF('บันทึกรายการ 63'!$B$257:$B$467,'Statement 63'!A43,'บันทึกรายการ 63'!$J$257:$J$467) -> 0 | I43: =G43-H43 -> 5769.34 | J43: =SUMIF('บันทึกรายการ 63'!$B$471:$B$647,'Statement 63'!A43,'บันทึกรายการ 63'!$I$471:$I$647) -> 6231.77 | K43: =SUMIF('บันทึกรายการ 63'!$B$471:$B$647,'Statement 63'!A43,'บันทึกรายการ 63'!$J$471:$J$647) -> 0 | L43: =J43-K43 -> 6231.77 | M43: =SUMIF('บันทึกรายการ 63'!$B$649:$B$819,'Statement 63'!A43,'บันทึกรายการ 63'!$I$649:$I$819) -> 5777.06 | N43: =SUMIF('บันทึกรายการ 63'!$B$649:$B$819,'Statement 63'!A43,'บันทึกรายการ 63'!$J$649:$J$819) -> 0 | O43: =M43-N43 -> 5777.06 | P43: =SUMIF('บันทึกรายการ 63'!$B$822:$B$994,'Statement 63'!A43,'บันทึกรายการ 63'!$I$822:$I$994) -> 4930.58 | Q43: =SUMIF('บันทึกรายการ 63'!$B$822:$B$994,'Statement 63'!A43,'บันทึกรายการ 63'!$J$822:$J$994) -> 0 | R43: =P43-Q43 -> 4930.58 | S43: =F43+I43+L43+O43+R43 -> 27572.57
A44: 5360-04 | B44: ค่าธรรมเนียมธนาคารและอื่นๆ | D44: =SUMIF('บันทึกรายการ 63'!$B$7:$B$254,'Statement 63'!A44,'บันทึกรายการ 63'!$I$7:$I$254) -> 0 | E44: =SUMIF('บันทึกรายการ 63'!$B$7:$B$254,'Statement 63'!A44,'บันทึกรายการ 63'!$J$7:$J$254) -> 0 | F44: =D44-E44 -> 0 | G44: =SUMIF('บันทึกรายการ 63'!$B$257:$B$467,'Statement 63'!A44,'บันทึกรายการ 63'!$I$257:$I$467) -> 0 | H44: =SUMIF('บันทึกรายการ 63'!$B$257:$B$467,'Statement 63'!A44,'บันทึกรายการ 63'!$J$257:$J$467) -> 0 | I44: =G44-H44 -> 0 | J44: =SUMIF('บันทึกรายการ 63'!$B$471:$B$647,'Statement 63'!A44,'บันทึกรายการ 63'!$I$471:$I$647) -> 0 | K44: =SUMIF('บันทึกรายการ 63'!$B$471:$B$647,'Statement 63'!A44,'บันทึกรายการ 63'!$J$471:$J$647) -> 0 | L44: =J44-K44 -> 0 | M44: =SUMIF('บันทึกรายการ 63'!$B$649:$B$819,'Statement 63'!A44,'บันทึกรายการ 63'!$I$649:$I$819) -> 0 | N44: =SUMIF('บันทึกรายการ 63'!$B$649:$B$819,'Statement 63'!A44,'บันทึกรายการ 63'!$J$649:$J$819) -> 0 | O44: =M44-N44 -> 0 | P44: =SUMIF('บันทึกรายการ 63'!$B$822:$B$994,'Statement 63'!A44,'บันทึกรายการ 63'!$I$822:$I$994) -> 0 | Q44: =SUMIF('บันทึกรายการ 63'!$B$822:$B$994,'Statement 63'!A44,'บันทึกรายการ 63'!$J$822:$J$994) -> 0 | R44: =P44-Q44 -> 0 | S44: =F44+I44+L44+O44+R44 -> 0
...

Sheet TB 63
A2: Chart of accounts | D2: ยอดยกมา ธ.ค.62 | F2: Debit (YTD) | G2: Credit (YTD) | H2: Balance
A3: 1111-00 | B3: เงินสด | D3: 5000 | F3: =SUMIF('บันทึกรายการ 63'!$B$7:$B$994,'TB 63'!A3,'บันทึกรายการ 63'!$I$7:$I$985) -> 2 | G3: =-SUMIF('บันทึกรายการ 63'!$B$7:$B$994,'TB 63'!A3,'บันทึกรายการ 63'!$J$7:$J$994) -> -5000 | H3: =D3+F3+G3 -> 2
A4: 1112-01 | B4: ธนาคารกสิกรไทย CA-040-1-57563-4 | D4: 198050.55 | F4: =SUMIF('บันทึกรายการ 63'!$B$7:$B$994,'TB 63'!A4,'บันทึกรายการ 63'!$I$7:$I$985) -> 300000 | G4: =-SUMIF('บันทึกรายการ 63'!$B$7:$B$994,'TB 63'!A4,'บันทึกรายการ 63'!$J$7:$J$994) -> -427099.07 | H4: =D4+F4+G4 -> 70951.48 | I4: 70951.48 | J4: =H4-I4 -> 0
A5: 1113-01 | B5: ธนาคารกสิกรไทย SA-040-1-56500-0 | D5: 735946.99 | F5: =SUMIF('บันทึกรายการ 63'!$B$7:$B$994,'TB 63'!A5,'บันทึกรายการ 63'!$I$7:$I$985) -> 535931.47 | G5: =-SUMIF('บันทึกรายการ 63'!$B$7:$B$994,'TB 63'!A5,'บันทึกรายการ 63'!$J$7:$J$994) -> -333000 | H5: =D5+F5+G5 -> 938878.46 | I5: 938878.46 | J5: =H5-I5 -> 0
A6: 1130-01 | B6: ลูกหนี้ค่าส่วนกลาง | D6: 376200 | F6: =SUMIF('บันทึกรายการ 63'!$B$7:$B$994,'TB 63'!A6,'บันทึกรายการ 63'!$I$7:$I$985) -> 0 | G6: =-SUMIF('บันทึกรายการ 63'!$B$7:$B$994,'TB 63'!A6,'บันทึกรายการ 63'!$J$7:$J$994) -> -72602.31 | H6: =D6+F6+G6 -> 303597.69
A7: 1151-02 | B7: ภาษีถูกหัก ณ ที่จ่ายล่วงหน้า | D7: 18.71 | F7: =SUMIF('บันทึกรายการ 63'!$B$7:$B$994,'TB 63'!A7,'บันทึกรายการ 63'!$I$7:$I$985) -> 0 | G7: =-SUMIF('บันทึกรายการ 63'!$B$7:$B$994,'TB 63'!A7,'บันทึกรายการ 63'!$J$7:$J$994) -> 0 | H7: =D7+F7+G7 -> 18.71
A8: 1152-00 | B8: เงินทดลองจ่าย (สำรองจ่าย) | D8: 1867.05 | F8: =SUMIF('บันทึกรายการ 63'!$B$7:$B$994,'TB 63'!A8,'บันทึกรายการ 63'!$I$7:$I$985) -> 10000 | G8: =-SUMIF('บันทึกรายการ 63'!$B$7:$B$994,'TB 63'!A8,'บันทึกรายการ 63'!$J$7:$J$994) -> -20000 | H8: =D8+F8+G8 -> -8132.95
A9: 1410-07 | B9: เครื่องตกแต่งสำนักงาน | D9: 19450 | F9: =SUMIF('บันทึกรายการ 63'!$B$7:$B$994,'TB 63'!A9,'บันทึกรายการ 63'!$I$7:$I$985) -> 0 | G9: =-SUMIF('บันทึกรายการ 63'!$B$7:$B$994,'TB 63'!A9,'บันทึกรายการ 63'!$J$7:$J$994) -> 0 | H9: =D9+F9+G9 -> 19450
A10: 2120-02 | B10: เช็คจ่ายล่วงหน้า | D10: 0 | F10: =SUMIF('บันทึกรายการ 63'!$B$7:$B$994,'TB 63'!A10,'บันทึกรายการ 63'!$I$7:$I$985) -> 0 | G10: =-SUMIF('บันทึกรายการ 63'!$B$7:$B$994,'TB 63'!A10,'บันทึกรายการ 63'!$J$7:$J$994) -> 0 | H10: =D10+F10+G10 -> 0
A11: 2131-02 | B11: ค่าเก็บขยะค้างจ่าย | D11: -3000 | F11: =SUMIF('บันทึกรายการ 63'!$B$7:$B$994,'TB 63'!A11,'บันทึกรายการ 63'!$I$7:$I$985) -> 15000 | G11: =-SUMIF('บันทึกรายการ 63'!$B$7:$B$994,'TB 63'!A11,'บันทึกรายการ 63'!$J$7:$J$994) -> -15000 | H11: =D11+F11+G11 -> -3000
A12: 2131-03 | B12: ค่าบริการดูแลสระว่ายน้ำค้างจ่าย | D12: -8500 | F12: =SUMIF('บันทึกรายการ 63'!$B$7:$B$994,'TB 63'!A12,'บันทึกรายการ 63'!$I$7:$I$985) -> 31000 | G12: =-SUMIF('บันทึกรายการ 63'!$B$7:$B$994,'TB 63'!A12,'บันทึกรายการ 63'!$J$7:$J$994) -> -22500 | H12: =D12+F12+G12 -> 0
A13: 2131-04 | B13: ค่ารักษาความปลอดภัยค้างจ่าย | D13: -38233.18 | F13: =SUMIF('บันทึกรายการ 63'!$B$7:$B$994,'TB 63'!A13,'บันทึกรายการ 63'!$I$7:$I$985) -> 192909.32 | G13: =-SUMIF('บันทึกรายการ 63'!$B$7:$B$994,'TB 63'!A13,'บันทึกรายการ 63'!$J$7:$J$994) -> -193490.46 | H13: =D13+F13+G13 -> -38814.32
A14: 2131-06 | B14: ค่าไฟฟ้าค้างจ่าย | D14: -3476.06 | F14: =SUMIF('บันทึกรายการ 63'!$B$7:$B$994,'TB 63'!A14,'บันทึกรายการ 63'!$I$7:$I$985) -> 26118.05 | G14: =-SUMIF('บันทึกรายการ 63'!$B$7:$B$994,'TB 63'!A14,'บันทึกรายการ 63'!$J$7:$J$994) -> -27572.57 | H14: =D14+F14+G14 -> -4930.58
A15: 2131-08 | B15: ค่าดูแลส่วนกลางค้างจ่าย | D15: -15000 | F15: =SUMIF('บันทึกรายการ 63'!$B$7:$B$994,'TB 63'!A15,'บันทึกรายการ 63'!$I$7:$I$985) -> 75000 | G15: =-SUMIF('บันทึกรายการ 63'!$B$7:$B$994,'TB 63'!A15,'บันทึกรายการ 63'!$J$7:$J$994) -> -75000 | H15: =D15+F15+G15 -> -15000
A16: 2131-09 | B16: ค่าดูแลส่วนกลางรับล่วงหน้า | D16: -600 | F16: =SUMIF('บันทึกรายการ 63'!$B$7:$B$994,'TB 63'!A16,'บันทึกรายการ 63'!$I$7:$I$985) -> 0 | G16: =-SUMIF('บันทึกรายการ 63'!$B$7:$B$994,'TB 63'!A16,'บันทึกรายการ 63'!$J$7:$J$994) -> -200 | H16: =D16+F16+G16 -> -800
A17: 2131-11 | B17: ค่าบริการทำบัญชีค้างจ่าย | D17: -32125 | F17: =SUMIF('บันทึกรายการ 63'!$B$7:$B$994,'TB 63'!A17,'บันทึกรายการ 63'!$I$7:$I$985) -> 32125 | G17: =-SUMIF('บันทึกรายการ 63'!$B$7:$B$994,'TB 63'!A17,'บันทึกรายการ 63'!$J$7:$J$994) -> 0 | H17: =D17+F17+G17 -> 0
... A20: 3100-00 | B20: เงินสนับสนุนจากโครงการ | D20: -1057329 | F20: =SUMIF('บันทึกรายการ 63'!$B$7:$B$994,'TB 63'!A20,'บันทึกรายการ 63'!$I$7:$I$985) -> 0 | G20: =-SUMIF('บันทึกรายการ 63'!$B$7:$B$994,'TB 63'!A20,'บันทึกรายการ 63'!$J$7:$J$994) -> 0 | H20: =D20+F20+G20 -> -1057329
A21: 3200-00 | B21: รายรับมากกว่ารายจ่ายต้นงวด | D21: =-5918.53-130051.53 -> -135970.06 | F21: =SUMIF('บันทึกรายการ 63'!$B$7:$B$994,'TB 63'!A21,'บันทึกรายการ 63'!$I$7:$I$985) -> 0 | G21: =-SUMIF('บันทึกรายการ 63'!$B$7:$B$994,'TB 63'!A21,'บันทึกรายการ 63'!$J$7:$J$994) -> 0 | H21: =D21+F21+G21 -> -135970.06
A24: 4100-01 | B24: รายรับค่าส่วนกลาง | F24: =SUMIF('บันทึกรายการ 63'!$B$7:$B$994,'TB 63'!A24,'บันทึกรายการ 63'!$I$7:$I$985) -> 7200 | G24: =-SUMIF('บันทึกรายการ 63'!$B$7:$B$994,'TB 63'!A24,'บันทึกรายการ 63'!$J$7:$J$994) -> -445629.16 | H24: =D24+F24+G24 -> -438429.16
A25: 4100-02 | B25: รายรับอื่นๆ | F25: =SUMIF('บันทึกรายการ 63'!$B$7:$B$994,'TB 63'!A25,'บันทึกรายการ 63'!$I$7:$I$985) -> 0 | G25: =-SUMIF('บันทึกรายการ 63'!$B$7:$B$994,'TB 63'!A25,'บันทึกรายการ 63'!$J$7:$J$994) -> 0 | H25: =D25+F25+G25 -> 0
A26: 4200-01 | B26: ดอกเบี้ยรับ | F26: =SUMIF('บันทึกรายการ 63'!$B$7:$B$994,'TB 63'!A26,'บันทึกรายการ 63'!$I$7:$I$985) -> 0 | G26: =-SUMIF('บันทึกรายการ 63'!$B$7:$B$994,'TB 63'!A26,'บันทึกรายการ 63'!$J$7:$J$994) -> 0 | H26: =D26+F26+G26 -> 0
A27: 5110-09 | B27: ส่วนลดรับ | F27: =SUMIF('บันทึกรายการ 63'!$B$7:$B$994,'TB 63'!A27,'บันทึกรายการ 63'!$I$7:$I$985) -> 0 | G27: =-SUMIF('บันทึกรายการ 63'!$B$7:$B$994,'TB 63'!A27,'บันทึกรายการ 63'!$J$7:$J$994) -> 0 | H27: =D27+F27+G27 -> 0
A28: 5320-02 | B28: ค่าอะไหล่ซ่อมบำรุงและค่าซ่อมแซมอื่นๆ | F28: =SUMIF('บันทึกรายการ 63'!$B$7:$B$994,'TB 63'!A28,'บันทึกรายการ 63'!$I$7:$I$985) -> 83726.7 | G28: =-SUMIF('บันทึกรายการ 63'!$B$7:$B$994,'TB 63'!A28,'บันทึกรายการ 63'!$J$7:$J$994) -> 0 | H28: =D28+F28+G28 -> 83726.7
A29: 5320-03 | B29: วัสดุสิ้นเปลือง | F29: =SUMIF('บันทึกรายการ 63'!$B$7:$B$994,'TB 63'!A29,'บันทึกรายการ 63'!$I$7:$I$985) -> 1720 | G29: =-SUMIF('บันทึกรายการ 63'!$B$7:$B$994,'TB 63'!A29,'บันทึกรายการ 63'!$J$7:$J$994) -> 0 | H29: =D29+F29+G29 -> 1720
A30: 5320-05 | B30: ค่าดูแลส่วนกลาง | F30: =SUMIF('บันทึกรายการ 63'!$B$7:$B$994,'TB 63'!A30,'บันทึกรายการ 63'!$I$7:$I$985) -> 75000 | G30: =-SUMIF('บันทึกรายการ 63'!$B$7:$B$994,'TB 63'!A30,'บันทึกรายการ 63'!$J$7:$J$994) -> 0 | H30: =D30+F30+G30 -> 75000
A31: 5320-06 | B31: ค่ารักษาความปลอดภัย | F31: =SUMIF('บันทึกรายการ 63'!$B$7:$B$994,'TB 63'!A31,'บันทึกรายการ 63'!$I$7:$I$985) -> 193490.46 | G31: =-SUMIF('บันทึกรายการ 63'!$B$7:$B$994,'TB 63'!A31,'บันทึกรายการ 63'!$J$7:$J$994) -> 0 | H31: =D31+F31+G31 -> 193490.46
A32: 5320-07 | B32: ค่าเก็บขยะ | F32: =SUMIF('บันทึกรายการ 63'!$B$7:$B$994,'TB 63'!A32,'บันทึกรายการ 63'!$I$7:$I$985) -> 15000 | G32: =-SUMIF('บันทึกรายการ 63'!$B$7:$B$994,'TB 63'!A32,'บันทึกรายการ 63'!$J$7:$J$994) -> 0 | H32: =D32+F32+G32 -> 15000
A33: 5320-10 | B33: ค่าบริการดูแลสระว่ายน้ำ | F33: =SUMIF('บันทึกรายการ 63'!$B$7:$B$994,'TB 63'!A33,'บันทึกรายการ 63'!$I$7:$I$985) -> 22500 | G33: =-SUMIF('บันทึกรายการ 63'!$B$7:$B$994,'TB 63'!A33,'บันทึกรายการ 63'!$J$7:$J$994) -> 0 | H33: =D33+F33+G33 -> 22500
A34: 5330-01 | B34: ค่าไฟฟ้า | F34: =SUMIF('บันทึกรายการ 63'!$B$7:$B$994,'TB 63'!A34,'บันทึกรายการ 63'!$I$7:$I$985) -> 27572.57 | G34: =-SUMIF('บันทึกรายการ 63'!$B$7:$B$994,'TB 63'!A34,'บันทึกรายการ 63'!$J$7:$J$994) -> 0 | H34: =D34+F34+G34 -> 27572.57
A35: 5360-04 | B35: ค่าธรรมเนียมธนาคารและอื่นๆ | F35: =SUMIF('บันทึกรายการ 63'!$B$7:$B$994,'TB 63'!A35,'บันทึกรายการ 63'!$I$7:$I$985) -> 0 | G35: =-SUMIF('บันทึกรายการ 63'!$B$7:$B$994,'TB 63'!A35,'บันทึกรายการ 63'!$J$7:$J$994) -> 0 | H35: =D35+F35+G35 -> 0
... A38: 5390-04 | B38: ค่าใช้จ่ายต้องห้าม | F38: =SUMIF('บันทึกรายการ 63'!$B$7:$B$994,'TB 63'!A38,'บันทึกรายการ 63'!$I$7:$I$985) -> 0 | G38: =-SUMIF('บันทึกรายการ 63'!$B$7:$B$994,'TB 63'!A38,'บันทึกรายการ 63'!$J$7:$J$994) -> 0 | H38: =D38+F38+G38 -> 0
D40: =SUM(D3:D39) -> 2.910383e-10
D41: =SUM(D24:D38) -> 0 | F41: =SUM(F24:F38) -> 438207.73 | G41: =SUM(G24:G38) -> -445629.16 | H41: =SUM(H24:H38) -> -7421.43

Sheet Accounts chart
A2: Chart of accounts
A3: 1111-00 | B3: เงินสด
A4: 1112-01 | B4: ธนาคารกสิกรไทย CA-040-1-57563-4
A5: 1113-01 | B5: ธนาคารกสิกรไทย SA-040-1-56500-0
A6: 1130-01 | B6: ลูกหนี้ค่าส่วนกลาง
A7: 1151-02 | B7: ภาษีถูกหัก ณ ที่จ่ายล่วงหน้า
A8: 1152-00 | B8: เงินทดลองจ่าย (สำรองจ่าย)
A9: 1410-07 | B9: เครื่องตกแต่งสำนักงาน
A10: 2120-02 | B10: เช็คจ่ายล่วงหน้า
A11: 2131-02 | B11: ค่าเก็บขยะค้างจ่าย
A12: 2131-03 | B12: ค่าบริการดูแลสระว่ายน้ำค้างจ่าย
A13: 2131-04 | B13: ค่ารักษาความปลอดภัยค้างจ่าย
A14: 2131-06 | B14: ค่าไฟฟ้าค้างจ่าย
... A38: 5390-04 | B38: ค่าใช้จ่ายต้องห้าม
A45: ไว้แนบตั้งปรับปรุงลูกหนี้ 2562
A46: Chart of accounts
A47: 1111-00 | B47: เงินสด
A48: 1112-01 | B48: ธนาคารกสิกรไทย CA-040-1-57563-4
A49: 1113-01 | B49: ธนาคารกสิกรไทย SA-040-1-56500-0
A50: 1130-01 | B50: ลูกหนี้ค่าส่วนกลาง
A51: 1151-02 | B51: ภาษีถูกหัก ณ ที่จ่ายล่วงหน้า
A52: 1152-00 | B52: เงินทดลองจ่าย (สำรองจ่าย)
